Workbook

Sheet BÁO CÁO MỚI
H1: =+H3-G3 -> 1527250000
A2: TỔNG CÁC TRẠI | B2: Tổng số con | C2: Tổng Kg | D2: Trọng Iượng TB | E2: Giá TB công nợ | F2: Giá bán TB | G2: Tổng công nợ cty | H2: Tổng doanh thu bán | I2: Tổng tiền khách đã trả (Bao gồm cả khách bắn về cty) | J2: Tổng tiền Lâm Anh bắn về Cty | K2: Công nợ tháng cũ | L2: Dư nợ mới
B3: =+B6+B9+B12+B15+B18+B21 -> 755 | C3: =+C6+C9+C12+C15+C18+C21 -> 35505 | D3: =IFERROR(C3/B3,"-") -> 47.02649 | E3: =IFERROR(+G3/C3,"-") -> 38698.775 | F3: =IFERROR(+H3/C3,"-") -> 81713.843 | G3: =+G6+G9+G12+G15+G18+G21 -> 1374000000 | H3: =+H6+H9+H12+H15+H18+H21 -> 2901250000 | I3: =+I6+I9+I12+I15+I18+I21 -> 10500000 | J3: =+'MAIL CÔNG NỢ'!C6 -> 0 | K3: =+'MAIL CÔNG NỢ'!D6 -> 0 | L3: =+J3-K3-G3 -> -1374000000
A5: RTD | B5: Tổng số con | C5: Tổng Kg | D5: Trọng Iượng TB | E5: Giá TB công nợ | F5: Giá bán TB | G5: Tổng công nợ cty | H5: Tổng doanh thu bán | I5: Tổng tiền khách đã trả (Bao gồm cả khách bắn về cty) | J5: Tổng tiền Lâm Anh bắn về Cty
B6: =+SUMIFS($D$28:$D$107,$C$28:$C$107,$A5) -> 605 | C6: =+SUMIFS($E$28:$E$107,$C$28:$C$107,$A5) -> 17505 | D6: =IFERROR(C6/B6,"-") -> 28.933884 | E6: - | F6: =IFERROR(+H6/C6,"-") -> 110211.37 | G6: =+SUMIFS($F$28:$F$107,$C$28:$C$107,$A5) -> 1374000000 | H6: =+SUMIFS($G$28:$G$107,$C$28:$C$107,$A5) -> 1929250000 | I6: =+SUMIFS($I$28:$I$107,$C$28:$C$107,$A5)+SUMIFS($J$28:$J$107,$C$28:$C$107,$A5) -> 10500000 | J6: =+SUMIFS('MAIL CÔNG NỢ'!$D:$D,'MAIL CÔNG NỢ'!$F:$F,'BÁO CÁO MỚI'!$A5) -> 0 | K6: =+SUMIFS('MAIL CÔNG NỢ'!$D$8:$D$13,'MAIL CÔNG NỢ'!$B$8:$B$13,'BÁO CÁO MỚI'!A5) -> 0 | L6: =+J6-K6-G6 -> -1374000000
A8: TAM DƯƠNG | B8: Tổng số con | C8: Tổng Kg | D8: Trọng Iượng TB | E8: Giá TB công nợ | F8: Giá bán TB | G8: Tổng công nợ cty | H8: Tổng doanh thu bán | I8: Tổng tiền khách đã trả (Bao gồm cả khách bắn về cty) | J8: Tổng tiền Lâm Anh bắn về Cty
B9: =+SUMIFS($D$28:$D$107,$C$28:$C$107,$A8) -> 0 | C9: =+SUMIFS($E$28:$E$107,$C$28:$C$107,$A8) -> 0 | D9: =IFERROR(C9/B9,"-") -> - | E9: - | F9: =IFERROR(+H9/C9,"-") -> - | G9: =+SUMIFS($F$28:$F$107,$C$28:$C$107,$A8) -> 0 | H9: =+SUMIFS($G$28:$G$107,$C$28:$C$107,$A8) -> 0 | I9: =+SUMIFS($I$28:$I$107,$C$28:$C$107,$A8)+SUMIFS($J$28:$J$107,$C$28:$C$107,$A8) -> 0 | J9: =+SUMIFS('MAIL CÔNG NỢ'!$D:$D,'MAIL CÔNG NỢ'!$F:$F,'BÁO CÁO MỚI'!$A8) -> 0 | K9: =+SUMIFS('MAIL CÔNG NỢ'!$D$8:$D$13,'MAIL CÔNG NỢ'!$B$8:$B$13,'BÁO CÁO MỚI'!A8) -> 0 | L9: =+J9-K9-G9 -> 0
A11: TIGER | B11: Tổng số con | C11: Tổng Kg | D11: Trọng Iượng TB | E11: Giá TB công nợ | F11: Giá bán TB | G11: Tổng công nợ cty | H11: Tổng doanh thu bán | I11: Tổng tiền khách đã trả (Bao gồm cả khách bắn về cty) | J11: Tổng tiền Lâm Anh bắn về Cty
B12: =+SUMIFS($D$28:$D$107,$C$28:$C$107,$A11) -> 150 | C12: =+SUMIFS($E$28:$E$107,$C$28:$C$107,$A11) -> 18000 | D12: =IFERROR(C12/B12,"-") -> 120 | E12: - | F12: =IFERROR(+H12/C12,"-") -> 54000 | G12: =+SUMIFS($F$28:$F$107,$C$28:$C$107,$A11) -> 0 | H12: =+SUMIFS($G$28:$G$107,$C$28:$C$107,$A11) -> 972000000 | I12: =+SUMIFS($I$28:$I$107,$C$28:$C$107,$A11)+SUMIFS($J$28:$J$107,$C$28:$C$107,$A11) -> 0 | J12: =+SUMIFS('MAIL CÔNG NỢ'!$D:$D,'MAIL CÔNG NỢ'!$F:$F,'BÁO CÁO MỚI'!$A11) -> 0 | K12: =+SUMIFS('MAIL CÔNG NỢ'!$D$8:$D$13,'MAIL CÔNG NỢ'!$B$8:$B$13,'BÁO CÁO MỚI'!A11) -> 0 | L12: =+J12-K12-G12 -> 0
A14: THANH HÓA | B14: Tổng số con | C14: Tổng Kg | D14: Trọng Iượng TB | E14: Giá TB công nợ | F14: Giá bán TB | G14: Tổng công nợ cty | H14: Tổng doanh thu bán | I14: Tổng tiền khách đã trả (Bao gồm cả khách bắn về cty) | J14: Tổng tiền Lâm Anh bắn về Cty
B15: =+SUMIFS($D$28:$D$107,$C$28:$C$107,$A14) -> 0 | C15: =+SUMIFS($E$28:$E$107,$C$28:$C$107,$A14) -> 0 | D15: =IFERROR(C15/B15,"-") -> - | E15: - | F15: =IFERROR(+H15/C15,"-") -> - | G15: =+SUMIFS($F$28:$F$107,$C$28:$C$107,$A14) -> 0 | H15: =+SUMIFS($G$28:$G$107,$C$28:$C$107,$A14) -> 0 | I15: =+SUMIFS($I$28:$I$107,$C$28:$C$107,$A14)+SUMIFS($J$28:$J$107,$C$28:$C$107,$A14) -> 0 | J15: =+SUMIFS('MAIL CÔNG NỢ'!$D:$D,'MAIL CÔNG NỢ'!$F:$F,'BÁO CÁO MỚI'!$A14) -> 0 | K15: =+SUMIFS('MAIL CÔNG NỢ'!$D$8:$D$13,'MAIL CÔNG NỢ'!$B$8:$B$13,'BÁO CÁO MỚI'!A14) -> 0 | L15: =+J15-K15-G15 -> 0
A17: APPE | B17: Tổng số con | C17: Tổng Kg | D17: Trọng Iượng TB | E17: Giá TB công nợ | F17: Giá bán TB | G17: Tổng công nợ cty | H17: Tổng doanh thu bán | I17: Tổng tiền khách đã trả (Bao gồm cả khách bắn về cty) | J17: Tổng tiền Lâm Anh bắn về Cty
B18: =+SUMIFS($D$28:$D$107,$C$28:$C$107,$A17) -> 0 | C18: =+SUMIFS($E$28:$E$107,$C$28:$C$107,$A17) -> 0 | D18: =IFERROR(C18/B18,"-") -> - | E18: - | F18: =IFERROR(+H18/C18,"-") -> - | G18: =+SUMIFS($F$28:$F$107,$C$28:$C$107,$A17) -> 0 | H18: =+SUMIFS($G$28:$G$107,$C$28:$C$107,$A17) -> 0 | I18: =+SUMIFS($I$28:$I$107,$C$28:$C$107,$A17)+SUMIFS($J$28:$J$107,$C$28:$C$107,$A17) -> 0 | J18: =+SUMIFS('MAIL CÔNG NỢ'!$D:$D,'MAIL CÔNG NỢ'!$F:$F,'BÁO CÁO MỚI'!$A17) -> 0 | K18: =+SUMIFS('MAIL CÔNG NỢ'!$D$8:$D$13,'MAIL CÔNG NỢ'!$B$8:$B$13,'BÁO CÁO MỚI'!A17) -> 0 | L18: =+J18-K18-G18 -> 0
A20: AVAC | B20: Tổng số con | C20: Tổng Kg | D20: Trọng Iượng TB | E20: Giá TB công nợ | F20: Giá bán TB | G20: Tổng công nợ cty | H20: Tổng doanh thu bán | I20: Tổng tiền khách đã trả (Bao gồm cả khách bắn về cty) | J20: Tổng tiền Lâm Anh bắn về Cty
B21: =+SUMIFS($D$28:$D$107,$C$28:$C$107,$A20) -> 0 | C21: =+SUMIFS($E$28:$E$107,$C$28:$C$107,$A20) -> 0 | D21: =IFERROR(C21/B21,"-") -> - | E21: - | F21: =IFERROR(+H21/C21,"-") -> - | G21: =+SUMIFS($F$28:$F$107,$C$28:$C$107,$A20) -> 0 | H21: =+SUMIFS($G$28:$G$107,$C$28:$C$107,$A20) -> 0 | I21: =+SUMIFS($I$28:$I$107,$C$28:$C$107,$A20)+SUMIFS($J$28:$J$107,$C$28:$C$107,$A20) -> 0 | J21: =+SUMIFS('MAIL CÔNG NỢ'!$D:$D,'MAIL CÔNG NỢ'!$F:$F,'BÁO CÁO MỚI'!$A20) -> 0 | K21: =+SUMIFS('MAIL CÔNG NỢ'!$D$8:$D$13,'MAIL CÔNG NỢ'!$B$8:$B$13,'BÁO CÁO MỚI'!A20) -> 0 | L21: =+J21-K21-G21 -> 0
B27: Trại | C27: Nhóm trại | D27: Tổng số con | E27: Tổng Kg | F27: Tổng công nợ cty | G27: Tổng doanh thu bán | H27: Trọng Iượng TB | I27: Khách chuyển về công ty | J27: Thu tiền từ khách
B28: Vĩnh Phúc Thịt | C28: =+VLOOKUP(B28,Data!F:G,2,0) -> RTD | D28: =+SUMIFS('Heo thịt_Nhập dữ liệu hàng ngày'!$P:$P,'Heo thịt_Nhập dữ liệu hàng ngày'!$L:$L,$B28)+SUMIFS('Heo con_Nhập dữ liệu'!$G:$G,'Heo con_Nhập dữ liệu'!$D:$D,'BÁO CÁO MỚI'!$B28) -> 0 | E28: =+SUMIFS('Heo thịt_Nhập dữ liệu hàng ngày'!$Q:$Q,'Heo thịt_Nhập dữ liệu hàng ngày'!$L:$L,$B28)+SUMIFS('Heo con_Nhập dữ liệu'!$H:$H,'Heo con_Nhập dữ liệu'!$D:$D,'BÁO CÁO MỚI'!$B28) -> 0 | F28: =+SUMIFS('Heo thịt_Nhập dữ liệu hàng ngày'!$X:$X,'Heo thịt_Nhập dữ liệu hàng ngày'!$L:$L,$B28)+SUMIFS('Heo con_Nhập dữ liệu'!$O:$O,'Heo con_Nhập dữ liệu'!$D:$D,'BÁO CÁO MỚI'!$B28) -> 0 | G28: =+SUMIFS('Heo thịt_Nhập dữ liệu hàng ngày'!$U:$U,'Heo thịt_Nhập dữ liệu hàng ngày'!$L:$L,$B28)+SUMIFS('Heo con_Nhập dữ liệu'!$O:$O,'Heo con_Nhập dữ liệu'!$D:$D,'BÁO CÁO MỚI'!$B28) -> 0 | H28: =IFERROR(E28/D28,"-") -> - | I28: =+SUMIFS('Heo thịt_Nhập dữ liệu hàng ngày'!$AA:$AA,'Heo thịt_Nhập dữ liệu hàng ngày'!$L:$L,$B28)+SUMIFS('Heo con_Nhập dữ liệu'!$R:$R,'Heo con_Nhập dữ liệu'!$D:$D,'BÁO CÁO MỚI'!$B28) -> 0 | J28: =+SUMIFS('Heo thịt_Nhập dữ liệu hàng ngày'!$Y:$Y,'Heo thịt_Nhập dữ liệu hàng ngày'!$L:$L,$B28)+SUMIFS('Heo thịt_Nhập dữ liệu hàng ngày'!$Z:$Z,'Heo thịt_Nhập dữ liệu hàng ngày'!$L:$L,$B28)+SUMIFS('Heo con_Nhập dữ liệu'!$P:$P,'Heo con_Nhập dữ liệu'!$D:$D,'BÁO CÁO MỚI'!$B28)+SUMIFS('Heo con_Nhập dữ liệu'!$Q:$Q,'Heo con_Nhập dữ liệu'!$D:$D,'BÁO CÁO MỚI'!$B28) -> 0
B29: Vĩnh Phúc Nái | C29: =+VLOOKUP(B29,Data!F:G,2,0) -> RTD | D29: =+SUMIFS('Heo thịt_Nhập dữ liệu hàng ngày'!$P:$P,'Heo thịt_Nhập dữ liệu hàng ngày'!$L:$L,$B29)+SUMIFS('Heo con_Nhập dữ liệu'!$G:$G,'Heo con_Nhập dữ liệu'!$D:$D,'BÁO CÁO MỚI'!$B29) -> 0 | E29: =+SUMIFS('Heo thịt_Nhập dữ liệu hàng ngày'!$Q:$Q,'Heo thịt_Nhập dữ liệu hàng ngày'!$L:$L,$B29)+SUMIFS('Heo con_Nhập dữ liệu'!$H:$H,'Heo con_Nhập dữ liệu'!$D:$D,'BÁO CÁO MỚI'!$B29) -> 0 | F29: =+SUMIFS('Heo thịt_Nhập dữ liệu hàng ngày'!$X:$X,'Heo thịt_Nhập dữ liệu hàng ngày'!$L:$L,$B29)+SUMIFS('Heo con_Nhập dữ liệu'!$O:$O,'Heo con_Nhập dữ liệu'!$D:$D,'BÁO CÁO MỚI'!$B29) -> 0 | G29: =+SUMIFS('Heo thịt_Nhập dữ liệu hàng ngày'!$U:$U,'Heo thịt_Nhập dữ liệu hàng ngày'!$L:$L,$B29)+SUMIFS('Heo con_Nhập dữ liệu'!$O:$O,'Heo con_Nhập dữ liệu'!$D:$D,'BÁO CÁO MỚI'!$B29) -> 0 | H29: =IFERROR(E29/D29,"-") -> - | I29: =+SUMIFS('Heo thịt_Nhập dữ liệu hàng ngày'!$AA:$AA,'Heo thịt_Nhập dữ liệu hàng ngày'!$L:$L,$B29)+SUMIFS('Heo con_Nhập dữ liệu'!$R:$R,'Heo con_Nhập dữ liệu'!$D:$D,'BÁO CÁO MỚI'!$B29) -> 0 | J29: =+SUMIFS('Heo thịt_Nhập dữ liệu hàng ngày'!$Y:$Y,'Heo thịt_Nhập dữ liệu hàng ngày'!$L:$L,$B29)+SUMIFS('Heo thịt_Nhập dữ liệu hàng ngày'!$Z:$Z,'Heo thịt_Nhập dữ liệu hàng ngày'!$L:$L,$B29)+SUMIFS('Heo con_Nhập dữ liệu'!$P:$P,'Heo con_Nhập dữ liệu'!$D:$D,'BÁO CÁO MỚI'!$B29)+SUMIFS('Heo con_Nhập dữ liệu'!$Q:$Q,'Heo con_Nhập dữ liệu'!$D:$D,'BÁO CÁO MỚI'!$B29) -> 0
B30: Phú Xuyên | C30: =+VLOOKUP(B30,Data!F:G,2,0) -> RTD | D30: =+SUMIFS('Heo thịt_Nhập dữ liệu hàng ngày'!$P:$P,'Heo thịt_Nhập dữ liệu hàng ngày'!$L:$L,$B30)+SUMIFS('Heo con_Nhập dữ liệu'!$G:$G,'Heo con_Nhập dữ liệu'!$D:$D,'BÁO CÁO MỚI'!$B30) -> 0 | E30: =+SUMIFS('Heo thịt_Nhập dữ liệu hàng ngày'!$Q:$Q,'Heo thịt_Nhập dữ liệu hàng ngày'!$L:$L,$B30)+SUMIFS('Heo con_Nhập dữ liệu'!$H:$H,'Heo con_Nhập dữ liệu'!$D:$D,'BÁO CÁO MỚI'!$B30) -> 0 | F30: =+SUMIFS('Heo thịt_Nhập dữ liệu hàng ngày'!$X:$X,'Heo thịt_Nhập dữ liệu hàng ngày'!$L:$L,$B30)+SUMIFS('Heo con_Nhập dữ liệu'!$O:$O,'Heo con_Nhập dữ liệu'!$D:$D,'BÁO CÁO MỚI'!$B30) -> 0 | G30: =+SUMIFS('Heo thịt_Nhập dữ liệu hàng ngày'!$U:$U,'Heo thịt_Nhập dữ liệu hàng ngày'!$L:$L,$B30)+SUMIFS('Heo con_Nhập dữ liệu'!$O:$O,'Heo con_Nhập dữ liệu'!$D:$D,'BÁO CÁO MỚI'!$B30) -> 0 | H30: =IFERROR(E30/D30,"-") -> - | I30: =+SUMIFS('Heo thịt_Nhập dữ liệu hàng ngày'!$AA:$AA,'Heo thịt_Nhập dữ liệu hàng ngày'!$L:$L,$B30)+SUMIFS('Heo con_Nhập dữ liệu'!$R:$R,'Heo con_Nhập dữ liệu'!$D:$D,'BÁO CÁO MỚI'!$B30) -> 0 | J30: =+SUMIFS('Heo thịt_Nhập dữ liệu hàng ngày'!$Y:$Y,'Heo thịt_Nhập dữ liệu hàng ngày'!$L:$L,$B30)+SUMIFS('Heo thịt_Nhập dữ liệu hàng ngày'!$Z:$Z,'Heo thịt_Nhập dữ liệu hàng ngày'!$L:$L,$B30)+SUMIFS('Heo con_Nhập dữ liệu'!$P:$P,'Heo con_Nhập dữ liệu'!$D:$D,'BÁO CÁO MỚI'!$B30)+SUMIFS('Heo con_Nhập dữ liệu'!$Q:$Q,'Heo con_Nhập dữ liệu'!$D:$D,'BÁO CÁO MỚI'!$B30) -> 0
B31: Bắc Giang Thịt | C31: =+VLOOKUP(B31,Data!F:G,2,0) -> RTD | D31: =+SUMIFS('Heo thịt_Nhập dữ liệu hàng ngày'!$P:$P,'Heo thịt_Nhập dữ liệu hàng ngày'!$L:$L,$B31)+SUMIFS('Heo con_Nhập dữ liệu'!$G:$G,'Heo con_Nhập dữ liệu'!$D:$D,'BÁO CÁO MỚI'!$B31) -> 105 | E31: =+SUMIFS('Heo thịt_Nhập dữ liệu hàng ngày'!$Q:$Q,'Heo thịt_Nhập dữ liệu hàng ngày'!$L:$L,$B31)+SUMIFS('Heo con_Nhập dữ liệu'!$H:$H,'Heo con_Nhập dữ liệu'!$D:$D,'BÁO CÁO MỚI'!$B31) -> 10505 | F31: =+SUMIFS('Heo thịt_Nhập dữ liệu hàng ngày'!$X:$X,'Heo thịt_Nhập dữ liệu hàng ngày'!$L:$L,$B31)+SUMIFS('Heo con_Nhập dữ liệu'!$O:$O,'Heo con_Nhập dữ liệu'!$D:$D,'BÁO CÁO MỚI'!$B31) -> 0 | G31: =+SUMIFS('Heo thịt_Nhập dữ liệu hàng ngày'!$U:$U,'Heo thịt_Nhập dữ liệu hàng ngày'!$L:$L,$B31)+SUMIFS('Heo con_Nhập dữ liệu'!$O:$O,'Heo con_Nhập dữ liệu'!$D:$D,'BÁO CÁO MỚI'!$B31) -> 555250000 | H31: =IFERROR(E31/D31,"-") -> 100.04762 | I31: =+SUMIFS('Heo thịt_Nhập dữ liệu hàng ngày'!$AA:$AA,'Heo thịt_Nhập dữ liệu hàng ngày'!$L:$L,$B31)+SUMIFS('Heo con_Nhập dữ liệu'!$R:$R,'Heo con_Nhập dữ liệu'!$D:$D,'BÁO CÁO MỚI'!$B31) -> 0 | J31: =+SUMIFS('Heo thịt_Nhập dữ liệu hàng ngày'!$Y:$Y,'Heo thịt_Nhập dữ liệu hàng ngày'!$L:$L,$B31)+SUMIFS('Heo thịt_Nhập dữ liệu hàng ngày'!$Z:$Z,'Heo thịt_Nhập dữ liệu hàng ngày'!$L:$L,$B31)+SUMIFS('Heo con_Nhập dữ liệu'!$P:$P,'Heo con_Nhập dữ liệu'!$D:$D,'BÁO CÁO MỚI'!$B31)+SUMIFS('Heo con_Nhập dữ liệu'!$Q:$Q,'Heo con_Nhập dữ liệu'!$D:$D,'BÁO CÁO MỚI'!$B31) -> 10000000
B32: Bắc Giang Nái | C32: =+VLOOKUP(B32,Data!F:G,2,0) -> RTD | D32: =+SUMIFS('Heo thịt_Nhập dữ liệu hàng ngày'!$P:$P,'Heo thịt_Nhập dữ liệu hàng ngày'!$L:$L,$B32)+SUMIFS('Heo con_Nhập dữ liệu'!$G:$G,'Heo con_Nhập dữ liệu'!$D:$D,'BÁO CÁO MỚI'!$B32) -> 500 | E32: =+SUMIFS('Heo thịt_Nhập dữ liệu hàng ngày'!$Q:$Q,'Heo thịt_Nhập dữ liệu hàng ngày'!$L:$L,$B32)+SUMIFS('Heo con_Nhập dữ liệu'!$H:$H,'Heo con_Nhập dữ liệu'!$D:$D,'BÁO CÁO MỚI'!$B32) -> 7000 | F32: =+SUMIFS('Heo thịt_Nhập dữ liệu hàng ngày'!$X:$X,'Heo thịt_Nhập dữ liệu hàng ngày'!$L:$L,$B32)+SUMIFS('Heo con_Nhập dữ liệu'!$O:$O,'Heo con_Nhập dữ liệu'!$D:$D,'BÁO CÁO MỚI'!$B32) -> 1374000000 | G32: =+SUMIFS('Heo thịt_Nhập dữ liệu hàng ngày'!$U:$U,'Heo thịt_Nhập dữ liệu hàng ngày'!$L:$L,$B32)+SUMIFS('Heo con_Nhập dữ liệu'!$O:$O,'Heo con_Nhập dữ liệu'!$D:$D,'BÁO CÁO MỚI'!$B32) -> 1374000000 | H32: =IFERROR(E32/D32,"-") -> 14 | I32: =+SUMIFS('Heo thịt_Nhập dữ liệu hàng ngày'!$AA:$AA,'Heo thịt_Nhập dữ liệu hàng ngày'!$L:$L,$B32)+SUMIFS('Heo con_Nhập dữ liệu'!$R:$R,'Heo con_Nhập dữ liệu'!$D:$D,'BÁO CÁO MỚI'!$B32) -> 0 | J32: =+SUMIFS('Heo thịt_Nhập dữ liệu hàng ngày'!$Y:$Y,'Heo thịt_Nhập dữ liệu hàng ngày'!$L:$L,$B32)+SUMIFS('Heo thịt_Nhập dữ liệu hàng ngày'!$Z:$Z,'Heo thịt_Nhập dữ liệu hàng ngày'!$L:$L,$B32)+SUMIFS('Heo con_Nhập dữ liệu'!$P:$P,'Heo con_Nhập dữ liệu'!$D:$D,'BÁO CÁO MỚI'!$B32)+SUMIFS('Heo con_Nhập dữ liệu'!$Q:$Q,'Heo con_Nhập dữ liệu'!$D:$D,'BÁO CÁO MỚI'!$B32) -> 500000
B33: Phú Thọ | C33: =+VLOOKUP(B33,Data!F:G,2,0) -> Tiger | D33: =+SUMIFS('Heo thịt_Nhập dữ liệu hàng ngày'!$P:$P,'Heo thịt_Nhập dữ liệu hàng ngày'!$L:$L,$B33)+SUMIFS('Heo con_Nhập dữ liệu'!$G:$G,'Heo con_Nhập dữ liệu'!$D:$D,'BÁO CÁO MỚI'!$B33) -> 0 | E33: =+SUMIFS('Heo thịt_Nhập dữ liệu hàng ngày'!$Q:$Q,'Heo thịt_Nhập dữ liệu hàng ngày'!$L:$L,$B33)+SUMIFS('Heo con_Nhập dữ liệu'!$H:$H,'Heo con_Nhập dữ liệu'!$D:$D,'BÁO CÁO MỚI'!$B33) -> 0 | F33: =+SUMIFS('Heo thịt_Nhập dữ liệu hàng ngày'!$X:$X,'Heo thịt_Nhập dữ liệu hàng ngày'!$L:$L,$B33)+SUMIFS('Heo con_Nhập dữ liệu'!$O:$O,'Heo con_Nhập dữ liệu'!$D:$D,'BÁO CÁO MỚI'!$B33) -> 0 | G33: =+SUMIFS('Heo thịt_Nhập dữ liệu hàng ngày'!$U:$U,'Heo thịt_Nhập dữ liệu hàng ngày'!$L:$L,$B33)+SUMIFS('Heo con_Nhập dữ liệu'!$O:$O,'Heo con_Nhập dữ liệu'!$D:$D,'BÁO CÁO MỚI'!$B33) -> 0 | H33: =IFERROR(E33/D33,"-") -> - | I33: =+SUMIFS('Heo thịt_Nhập dữ liệu hàng ngày'!$AA:$AA,'Heo thịt_Nhập dữ liệu hàng ngày'!$L:$L,$B33)+SUMIFS('Heo con_Nhập dữ liệu'!$R:$R,'Heo con_Nhập dữ liệu'!$D:$D,'BÁO CÁO MỚI'!$B33) -> 0 | J33: =+SUMIFS('Heo thịt_Nhập dữ liệu hàng ngày'!$Y:$Y,'Heo thịt_Nhập dữ liệu hàng ngày'!$L:$L,$B33)+SUMIFS('Heo thịt_Nhập dữ liệu hàng ngày'!$Z:$Z,'Heo thịt_Nhập dữ liệu hàng ngày'!$L:$L,$B33)+SUMIFS('Heo con_Nhập dữ liệu'!$P:$P,'Heo con_Nhập dữ liệu'!$D:$D,'BÁO CÁO MỚI'!$B33)+SUMIFS('Heo con_Nhập dữ liệu'!$Q:$Q,'Heo con_Nhập dữ liệu'!$D:$D,'BÁO CÁO MỚI'!$B33) -> 0
B34: Phú Thọ 2 | C34: =+VLOOKUP(B34,Data!F:G,2,0) -> RTD | D34: =+SUMIFS('Heo thịt_Nhập dữ liệu hàng ngày'!$P:$P,'Heo thịt_Nhập dữ liệu hàng ngày'!$L:$L,$B34)+SUMIFS('Heo con_Nhập dữ liệu'!$G:$G,'Heo con_Nhập dữ liệu'!$D:$D,'BÁO CÁO MỚI'!$B34) -> 0 | E34: =+SUMIFS('Heo thịt_Nhập dữ liệu hàng ngày'!$Q:$Q,'Heo thịt_Nhập dữ liệu hàng ngày'!$L:$L,$B34)+SUMIFS('Heo con_Nhập dữ liệu'!$H:$H,'Heo con_Nhập dữ liệu'!$D:$D,'BÁO CÁO MỚI'!$B34) -> 0 | F34: =+SUMIFS('Heo thịt_Nhập dữ liệu hàng ngày'!$X:$X,'Heo thịt_Nhập dữ liệu hàng ngày'!$L:$L,$B34)+SUMIFS('Heo con_Nhập dữ liệu'!$O:$O,'Heo con_Nhập dữ liệu'!$D:$D,'BÁO CÁO MỚI'!$B34) -> 0 | G34: =+SUMIFS('Heo thịt_Nhập dữ liệu hàng ngày'!$U:$U,'Heo thịt_Nhập dữ liệu hàng ngày'!$L:$L,$B34)+SUMIFS('Heo con_Nhập dữ liệu'!$O:$O,'Heo con_Nhập dữ liệu'!$D:$D,'BÁO CÁO MỚI'!$B34) -> 0 | H34: =IFERROR(E34/D34,"-") -> - | I34: =+SUMIFS('Heo thịt_Nhập dữ liệu hàng ngày'!$AA:$AA,'Heo thịt_Nhập dữ liệu hàng ngày'!$L:$L,$B34)+SUMIFS('Heo con_Nhập dữ liệu'!$R:$R,'Heo con_Nhập dữ liệu'!$D:$D,'BÁO CÁO MỚI'!$B34) -> 0 | J34: =+SUMIFS('Heo thịt_Nhập dữ liệu hàng ngày'!$Y:$Y,'Heo thịt_Nhập dữ liệu hàng ngày'!$L:$L,$B34)+SUMIFS('Heo thịt_Nhập dữ liệu hàng ngày'!$Z:$Z,'Heo thịt_Nhập dữ liệu hàng ngày'!$L:$L,$B34)+SUMIFS('Heo con_Nhập dữ liệu'!$P:$P,'Heo con_Nhập dữ liệu'!$D:$D,'BÁO CÁO MỚI'!$B34)+SUMIFS('Heo con_Nhập dữ liệu'!$Q:$Q,'Heo con_Nhập dữ liệu'!$D:$D,'BÁO CÁO MỚI'!$B34) -> 0
B35: Yên Bái | C35: =+VLOOKUP(B35,Data!F:G,2,0) -> Tiger | D35: =+SUMIFS('Heo thịt_Nhập dữ liệu hàng ngày'!$P:$P,'Heo thịt_Nhập dữ liệu hàng ngày'!$L:$L,$B35)+SUMIFS('Heo con_Nhập dữ liệu'!$G:$G,'Heo con_Nhập dữ liệu'!$D:$D,'BÁO CÁO MỚI'!$B35) -> 150 | E35: =+SUMIFS('Heo thịt_Nhập dữ liệu hàng ngày'!$Q:$Q,'Heo thịt_Nhập dữ liệu hàng ngày'!$L:$L,$B35)+SUMIFS('Heo con_Nhập dữ liệu'!$H:$H,'Heo con_Nhập dữ liệu'!$D:$D,'BÁO CÁO MỚI'!$B35) -> 18000 | F35: =+SUMIFS('Heo thịt_Nhập dữ liệu hàng ngày'!$X:$X,'Heo thịt_Nhập dữ liệu hàng ngày'!$L:$L,$B35)+SUMIFS('Heo con_Nhập dữ liệu'!$O:$O,'Heo con_Nhập dữ liệu'!$D:$D,'BÁO CÁO MỚI'!$B35) -> 0 | G35: =+SUMIFS('Heo thịt_Nhập dữ liệu hàng ngày'!$U:$U,'Heo thịt_Nhập dữ liệu hàng ngày'!$L:$L,$B35)+SUMIFS('Heo con_Nhập dữ liệu'!$O:$O,'Heo con_Nhập dữ liệu'!$D:$D,'BÁO CÁO MỚI'!$B35) -> 972000000 | H35: =IFERROR(E35/D35,"-") -> 120 | I35: =+SUMIFS('Heo thịt_Nhập dữ liệu hàng ngày'!$AA:$AA,'Heo thịt_Nhập dữ liệu hàng ngày'!$L:$L,$B35)+SUMIFS('Heo con_Nhập dữ liệu'!$R:$R,'Heo con_Nhập dữ liệu'!$D:$D,'BÁO CÁO MỚI'!$B35) -> 0 | J35: =+SUMIFS('Heo thịt_Nhập dữ liệu hàng ngày'!$Y:$Y,'Heo thịt_Nhập dữ liệu hàng ngày'!$L:$L,$B35)+SUMIFS('Heo thịt_Nhập dữ liệu hàng ngày'!$Z:$Z,'Heo thịt_Nhập dữ liệu hàng ngày'!$L:$L,$B35)+SUMIFS('Heo con_Nhập dữ liệu'!$P:$P,'Heo con_Nhập dữ liệu'!$D:$D,'BÁO CÁO MỚI'!$B35)+SUMIFS('Heo con_Nhập dữ liệu'!$Q:$Q,'Heo con_Nhập dữ liệu'!$D:$D,'BÁO CÁO MỚI'!$B35) -> 0
B36: Lục Nam | C36: =+VLOOKUP(B36,Data!F:G,2,0) -> Tiger | D36: =+SUMIFS('Heo thịt_Nhập dữ liệu hàng ngày'!$P:$P,'Heo thịt_Nhập dữ liệu hàng ngày'!$L:$L,$B36)+SUMIFS('Heo con_Nhập dữ liệu'!$G:$G,'Heo con_Nhập dữ liệu'!$D:$D,'BÁO CÁO MỚI'!$B36) -> 0 | E36: =+SUMIFS('Heo thịt_Nhập dữ liệu hàng ngày'!$Q:$Q,'Heo thịt_Nhập dữ liệu hàng ngày'!$L:$L,$B36)+SUMIFS('Heo con_Nhập dữ liệu'!$H:$H,'Heo con_Nhập dữ liệu'!$D:$D,'BÁO CÁO MỚI'!$B36) -> 0 | F36: =+SUMIFS('Heo thịt_Nhập dữ liệu hàng ngày'!$X:$X,'Heo thịt_Nhập dữ liệu hàng ngày'!$L:$L,$B36)+SUMIFS('Heo con_Nhập dữ liệu'!$O:$O,'Heo con_Nhập dữ liệu'!$D:$D,'BÁO CÁO MỚI'!$B36) -> 0 | G36: =+SUMIFS('Heo thịt_Nhập dữ liệu hàng ngày'!$U:$U,'Heo thịt_Nhập dữ liệu hàng ngày'!$L:$L,$B36)+SUMIFS('Heo con_Nhập dữ liệu'!$O:$O,'Heo con_Nhập dữ liệu'!$D:$D,'BÁO CÁO MỚI'!$B36) -> 0 | H36: =IFERROR(E36/D36,"-") -> - | I36: =+SUMIFS('Heo thịt_Nhập dữ liệu hàng ngày'!$AA:$AA,'Heo thịt_Nhập dữ liệu hàng ngày'!$L:$L,$B36)+SUMIFS('Heo con_Nhập dữ liệu'!$R:$R,'Heo con_Nhập dữ liệu'!$D:$D,'BÁO CÁO MỚI'!$B36) -> 0 | J36: =+SUMIFS('Heo thịt_Nhập dữ liệu hàng ngày'!$Y:$Y,'Heo thịt_Nhập dữ liệu hàng ngày'!$L:$L,$B36)+SUMIFS('Heo thịt_Nhập dữ liệu hàng ngày'!$Z:$Z,'Heo thịt_Nhập dữ liệu hàng ngày'!$L:$L,$B36)+SUMIFS('Heo con_Nhập dữ liệu'!$P:$P,'Heo con_Nhập dữ liệu'!$D:$D,'BÁO CÁO MỚI'!$B36)+SUMIFS('Heo con_Nhập dữ liệu'!$Q:$Q,'Heo con_Nhập dữ liệu'!$D:$D,'BÁO CÁO MỚI'!$B36) -> 0
B37: Lục Ngạn | C37: =+VLOOKUP(B37,Data!F:G,2,0) -> RTD | D37: =+SUMIFS('Heo thịt_Nhập dữ liệu hàng ngày'!$P:$P,'Heo thịt_Nhập dữ liệu hàng ngày'!$L:$L,$B37)+SUMIFS('Heo con_Nhập dữ liệu'!$G:$G,'Heo con_Nhập dữ liệu'!$D:$D,'BÁO CÁO MỚI'!$B37) -> 0 | E37: =+SUMIFS('Heo thịt_Nhập dữ liệu hàng ngày'!$Q:$Q,'Heo thịt_Nhập dữ liệu hàng ngày'!$L:$L,$B37)+SUMIFS('Heo con_Nhập dữ liệu'!$H:$H,'Heo con_Nhập dữ liệu'!$D:$D,'BÁO CÁO MỚI'!$B37) -> 0 | F37: =+SUMIFS('Heo thịt_Nhập dữ liệu hàng ngày'!$X:$X,'Heo thịt_Nhập dữ liệu hàng ngày'!$L:$L,$B37)+SUMIFS('Heo con_Nhập dữ liệu'!$O:$O,'Heo con_Nhập dữ liệu'!$D:$D,'BÁO CÁO MỚI'!$B37) -> 0 | G37: =+SUMIFS('Heo thịt_Nhập dữ liệu hàng ngày'!$U:$U,'Heo thịt_Nhập dữ liệu hàng ngày'!$L:$L,$B37)+SUMIFS('Heo con_Nhập dữ liệu'!$O:$O,'Heo con_Nhập dữ liệu'!$D:$D,'BÁO CÁO MỚI'!$B37) -> 0 | H37: =IFERROR(E37/D37,"-") -> - | I37: =+SUMIFS('Heo thịt_Nhập dữ liệu hàng ngày'!$AA:$AA,'Heo thịt_Nhập dữ liệu hàng ngày'!$L:$L,$B37)+SUMIFS('Heo con_Nhập dữ liệu'!$R:$R,'Heo con_Nhập dữ liệu'!$D:$D,'BÁO CÁO MỚI'!$B37) -> 0 | J37: =+SUMIFS('Heo thịt_Nhập dữ liệu hàng ngày'!$Y:$Y,'Heo thịt_Nhập dữ liệu hàng ngày'!$L:$L,$B37)+SUMIFS('Heo thịt_Nhập dữ liệu hàng ngày'!$Z:$Z,'Heo thịt_Nhập dữ liệu hàng ngày'!$L:$L,$B37)+SUMIFS('Heo con_Nhập dữ liệu'!$P:$P,'Heo con_Nhập dữ liệu'!$D:$D,'BÁO CÁO MỚI'!$B37)+SUMIFS('Heo con_Nhập dữ liệu'!$Q:$Q,'Heo con_Nhập dữ liệu'!$D:$D,'BÁO CÁO MỚI'!$B37) -> 0
B38: Tiger Thái Nguyên | C38: =+VLOOKUP(B38,Data!F:G,2,0) -> Tiger | D38: =+SUMIFS('Heo thịt_Nhập dữ liệu hàng ngày'!$P:$P,'Heo thịt_Nhập dữ liệu hàng ngày'!$L:$L,$B38)+SUMIFS('Heo con_Nhập dữ liệu'!$G:$G,'Heo con_Nhập dữ liệu'!$D:$D,'BÁO CÁO MỚI'!$B38) -> 0 | E38: =+SUMIFS('Heo thịt_Nhập dữ liệu hàng ngày'!$Q:$Q,'Heo thịt_Nhập dữ liệu hàng ngày'!$L:$L,$B38)+SUMIFS('Heo con_Nhập dữ liệu'!$H:$H,'Heo con_Nhập dữ liệu'!$D:$D,'BÁO CÁO MỚI'!$B38) -> 0 | F38: =+SUMIFS('Heo thịt_Nhập dữ liệu hàng ngày'!$X:$X,'Heo thịt_Nhập dữ liệu hàng ngày'!$L:$L,$B38)+SUMIFS('Heo con_Nhập dữ liệu'!$O:$O,'Heo con_Nhập dữ liệu'!$D:$D,'BÁO CÁO MỚI'!$B38) -> 0 | G38: =+SUMIFS('Heo thịt_Nhập dữ liệu hàng ngày'!$U:$U,'Heo thịt_Nhập dữ liệu hàng ngày'!$L:$L,$B38)+SUMIFS('Heo con_Nhập dữ liệu'!$O:$O,'Heo con_Nhập dữ liệu'!$D:$D,'BÁO CÁO MỚI'!$B38) -> 0 | H38: =IFERROR(E38/D38,"-") -> - | I38: =+SUMIFS('Heo thịt_Nhập dữ liệu hàng ngày'!$AA:$AA,'Heo thịt_Nhập dữ liệu hàng ngày'!$L:$L,$B38)+SUMIFS('Heo con_Nhập dữ liệu'!$R:$R,'Heo con_Nhập dữ liệu'!$D:$D,'BÁO CÁO MỚI'!$B38) -> 0 | J38: =+SUMIFS('Heo thịt_Nhập dữ liệu hàng ngày'!$Y:$Y,'Heo thịt_Nhập dữ liệu hàng ngày'!$L:$L,$B38)+SUMIFS('Heo thịt_Nhập dữ liệu hàng ngày'!$Z:$Z,'Heo thịt_Nhập dữ liệu hàng ngày'!$L:$L,$B38)+SUMIFS('Heo con_Nhập dữ liệu'!$P:$P,'Heo con_Nhập dữ liệu'!$D:$D,'BÁO CÁO MỚI'!$B38)+SUMIFS('Heo con_Nhập dữ liệu'!$Q:$Q,'Heo con_Nhập dữ liệu'!$D:$D,'BÁO CÁO MỚI'!$B38) -> 0
B39: Tiger Phú Thọ 3 (Thanh Sơn) | C39: =+VLOOKUP(B39,Data!F:G,2,0) -> Tiger | D39: =+SUMIFS('Heo thịt_Nhập dữ liệu hàng ngày'!$P:$P,'Heo thịt_Nhập dữ liệu hàng ngày'!$L:$L,$B39)+SUMIFS('Heo con_Nhập dữ liệu'!$G:$G,'Heo con_Nhập dữ liệu'!$D:$D,'BÁO CÁO MỚI'!$B39) -> 0 | E39: =+SUMIFS('Heo thịt_Nhập dữ liệu hàng ngày'!$Q:$Q,'Heo thịt_Nhập dữ liệu hàng ngày'!$L:$L,$B39)+SUMIFS('Heo con_Nhập dữ liệu'!$H:$H,'Heo con_Nhập dữ liệu'!$D:$D,'BÁO CÁO MỚI'!$B39) -> 0 | F39: =+SUMIFS('Heo thịt_Nhập dữ liệu hàng ngày'!$X:$X,'Heo thịt_Nhập dữ liệu hàng ngày'!$L:$L,$B39)+SUMIFS('Heo con_Nhập dữ liệu'!$O:$O,'Heo con_Nhập dữ liệu'!$D:$D,'BÁO CÁO MỚI'!$B39) -> 0 | G39: =+SUMIFS('Heo thịt_Nhập dữ liệu hàng ngày'!$U:$U,'Heo thịt_Nhập dữ liệu hàng ngày'!$L:$L,$B39)+SUMIFS('Heo con_Nhập dữ liệu'!$O:$O,'Heo con_Nhập dữ liệu'!$D:$D,'BÁO CÁO MỚI'!$B39) -> 0 | H39: =IFERROR(E39/D39,"-") -> - | I39: =+SUMIFS('Heo thịt_Nhập dữ liệu hàng ngày'!$AA:$AA,'Heo thịt_Nhập dữ liệu hàng ngày'!$L:$L,$B39)+SUMIFS('Heo con_Nhập dữ liệu'!$R:$R,'Heo con_Nhập dữ liệu'!$D:$D,'BÁO CÁO MỚI'!$B39) -> 0 | J39: =+SUMIFS('Heo thịt_Nhập dữ liệu hàng ngày'!$Y:$Y,'Heo thịt_Nhập dữ liệu hàng ngày'!$L:$L,$B39)+SUMIFS('Heo thịt_Nhập dữ liệu hàng ngày'!$Z:$Z,'Heo thịt_Nhập dữ liệu hàng ngày'!$L:$L,$B39)+SUMIFS('Heo con_Nhập dữ liệu'!$P:$P,'Heo con_Nhập dữ liệu'!$D:$D,'BÁO CÁO MỚI'!$B39)+SUMIFS('Heo con_Nhập dữ liệu'!$Q:$Q,'Heo con_Nhập dữ liệu'!$D:$D,'BÁO CÁO MỚI'!$B39) -> 0
... B47: Thái Bình | C47: =+VLOOKUP(B47,Data!F:G,2,0) -> Tam Dương | D47: =+SUMIFS('Heo thịt_Nhập dữ liệu hàng ngày'!$P:$P,'Heo thịt_Nhập dữ liệu hàng ngày'!$L:$L,$B47)+SUMIFS('Heo con_Nhập dữ liệu'!$G:$G,'Heo con_Nhập dữ liệu'!$D:$D,'BÁO CÁO MỚI'!$B47) -> 0 | E47: =+SUMIFS('Heo thịt_Nhập dữ liệu hàng ngày'!$Q:$Q,'Heo thịt_Nhập dữ liệu hàng ngày'!$L:$L,$B47)+SUMIFS('Heo con_Nhập dữ liệu'!$H:$H,'Heo con_Nhập dữ liệu'!$D:$D,'BÁO CÁO MỚI'!$B47) -> 0 | F47: =+SUMIFS('Heo thịt_Nhập dữ liệu hàng ngày'!$X:$X,'Heo thịt_Nhập dữ liệu hàng ngày'!$L:$L,$B47)+SUMIFS('Heo con_Nhập dữ liệu'!$O:$O,'Heo con_Nhập dữ liệu'!$D:$D,'BÁO CÁO MỚI'!$B47) -> 0 | G47: =+SUMIFS('Heo thịt_Nhập dữ liệu hàng ngày'!$U:$U,'Heo thịt_Nhập dữ liệu hàng ngày'!$L:$L,$B47)+SUMIFS('Heo con_Nhập dữ liệu'!$O:$O,'Heo con_Nhập dữ liệu'!$D:$D,'BÁO CÁO MỚI'!$B47) -> 0 | H47: =IFERROR(E47/D47,"-") -> - | I47: =+SUMIFS('Heo thịt_Nhập dữ liệu hàng ngày'!$AA:$AA,'Heo thịt_Nhập dữ liệu hàng ngày'!$L:$L,$B47)+SUMIFS('Heo con_Nhập dữ liệu'!$R:$R,'Heo con_Nhập dữ liệu'!$D:$D,'BÁO CÁO MỚI'!$B47) -> 0 | J47: =+SUMIFS('Heo thịt_Nhập dữ liệu hàng ngày'!$Y:$Y,'Heo thịt_Nhập dữ liệu hàng ngày'!$L:$L,$B47)+SUMIFS('Heo thịt_Nhập dữ liệu hàng ngày'!$Z:$Z,'Heo thịt_Nhập dữ liệu hàng ngày'!$L:$L,$B47)+SUMIFS('Heo con_Nhập dữ liệu'!$P:$P,'Heo con_Nhập dữ liệu'!$D:$D,'BÁO CÁO MỚI'!$B47)+SUMIFS('Heo con_Nhập dữ liệu'!$Q:$Q,'Heo con_Nhập dữ liệu'!$D:$D,'BÁO CÁO MỚI'!$B47) -> 0

Sheet Theo dõi khách hàng heo thịt
Q1: =+Q8-R8 -> 0
M2: TỔNG | Q2: =SUM(Q5:Q29) -> 0 | R2: =SUM(R5:R29) -> 0 | S2: =SUM(S5:S29) -> 0 | T2: =SUM(T5:T29) -> 0 | U2: =+T2-S2 -> 0
B3: TỔNG | D3: =SUM(D5:D600) -> 1527250000 | E3: =SUM(E5:E600) -> 10000000 | F3: =SUM(F5:F64) -> 1517250000 | G3: =SUM(G5:G64) -> 0 | H3: =SUBTOTAL(9,H5:H600) -> -972000000 | M3: STT | N3: Khách hàng (Nhập cột này) | O3: Địa chỉ | P3: Tên trại | Q3: Tiền hàng | R3: Đã thu | S3: Còn nợ | T3: Còn dư | U3: Thực tế
B4: STT | C4: Khách hàng | D4: Tiền hàng | E4: Đã thu | F4: Còn nợ | G4: Còn dư | H4: Thực tế | N4: Check theo thời gian | P4: 44774 | Q4: 44804
B5: 1 | C5: =IFERROR(Data!C4,"") -> 0 | D5: =SUMIFS('Heo thịt_Nhập dữ liệu hàng ngày'!$U:$U,'Heo thịt_Nhập dữ liệu hàng ngày'!$M:$M,'Theo dõi khách hàng heo thịt'!C5) -> 0 | E5: =SUMIFS('Heo thịt_Nhập dữ liệu hàng ngày'!$AB:$AB,'Heo thịt_Nhập dữ liệu hàng ngày'!$M:$M,'Theo dõi khách hàng heo thịt'!C5) -> 0 | F5: =SUMIFS('Heo thịt_Nhập dữ liệu hàng ngày'!$AC:$AC,'Heo thịt_Nhập dữ liệu hàng ngày'!$M:$M,'Theo dõi khách hàng heo thịt'!C5) -> 0 | G5: =SUMIFS('Heo thịt_Nhập dữ liệu hàng ngày'!$AD:$AD,'Heo thịt_Nhập dữ liệu hàng ngày'!$M:$M,'Theo dõi khách hàng heo thịt'!C5) -> 0 | H5: =+G5-F5 -> 0 | I5: =+ABS(H5) -> 0 | J5: =+IF(I5>500000,"check","-") -> - | K5: 20/9 | L5: =+H5*(-1) -> 0 | M5: 1 | N5: Khổng Văn Sơn | O5: =IFERROR(+VLOOKUP(N5,Data!C:D,2,0),"-") -> - | P5: Vĩnh Phúc Thịt | Q5: =IFERROR(SUMIFS('Heo thịt_Nhập dữ liệu hàng ngày'!$U:$U,'Heo thịt_Nhập dữ liệu hàng ngày'!$K:$K,">="&$P$4,'Heo thịt_Nhập dữ liệu hàng ngày'!$K:$K,"<="&'Theo dõi khách hàng heo thịt'!$Q$4,'Heo thịt_Nhập dữ liệu hàng ngày'!$L:$L,'Theo dõi khách hàng heo thịt'!P5,'Heo thịt_Nhập dữ liệu hàng ngày'!$M:$M,'Theo dõi khách hàng heo thịt'!$N$5),"-") -> 0 | R5: =IFERROR(SUMIFS('Heo thịt_Nhập dữ liệu hàng ngày'!$AB:$AB,'Heo thịt_Nhập dữ liệu hàng ngày'!$K:$K,">="&$P$4,'Heo thịt_Nhập dữ liệu hàng ngày'!$K:$K,"<="&'Theo dõi khách hàng heo thịt'!$Q$4,'Heo thịt_Nhập dữ liệu hàng ngày'!$L:$L,'Theo dõi khách hàng heo thịt'!P5,'Heo thịt_Nhập dữ liệu hàng ngày'!$M:$M,'Theo dõi khách hàng heo thịt'!$N$5),"-") -> 0 | S5: =IFERROR(SUMIFS('Heo thịt_Nhập dữ liệu hàng ngày'!$AC:$AC,'Heo thịt_Nhập dữ liệu hàng ngày'!$K:$K,">="&$P$4,'Heo thịt_Nhập dữ liệu hàng ngày'!$K:$K,"<="&'Theo dõi khách hàng heo thịt'!$Q$4,'Heo thịt_Nhập dữ liệu hàng ngày'!$L:$L,'Theo dõi khách hàng heo thịt'!P5,'Heo thịt_Nhập dữ liệu hàng ngày'!$M:$M,'Theo dõi khách hàng heo thịt'!$N$5),"-") -> 0 | T5: =IFERROR(SUMIFS('Heo thịt_Nhập dữ liệu hàng ngày'!$AD:$AD,'Heo thịt_Nhập dữ liệu hàng ngày'!$K:$K,">="&$P$4,'Heo thịt_Nhập dữ liệu hàng ngày'!$K:$K,"<="&'Theo dõi khách hàng heo thịt'!$Q$4,'Heo thịt_Nhập dữ liệu hàng ngày'!$L:$L,'Theo dõi khách hàng heo thịt'!P5,'Heo thịt_Nhập dữ liệu hàng ngày'!$M:$M,'Theo dõi khách hàng heo thịt'!$N$5),"-") -> 0 | U5: =IFERROR(+T5-S5,"-") -> 0
B6: 2 | C6: =IFERROR(Data!C5,"") -> nguyễn hữu viết | D6: =SUMIFS('Heo thịt_Nhập dữ liệu hàng ngày'!$U:$U,'Heo thịt_Nhập dữ liệu hàng ngày'!$M:$M,'Theo dõi khách hàng heo thịt'!C6) -> 555250000 | E6: =SUMIFS('Heo thịt_Nhập dữ liệu hàng ngày'!$AB:$AB,'Heo thịt_Nhập dữ liệu hàng ngày'!$M:$M,'Theo dõi khách hàng heo thịt'!C6) -> 10000000 | F6: =SUMIFS('Heo thịt_Nhập dữ liệu hàng ngày'!$AC:$AC,'Heo thịt_Nhập dữ liệu hàng ngày'!$M:$M,'Theo dõi khách hàng heo thịt'!C6) -> 545250000 | G6: =SUMIFS('Heo thịt_Nhập dữ liệu hàng ngày'!$AD:$AD,'Heo thịt_Nhập dữ liệu hàng ngày'!$M:$M,'Theo dõi khách hàng heo thịt'!C6) -> 0 | H6: =+G6-F6 -> -545250000 | I6: =+ABS(H6) -> 545250000 | J6: =+IF(I6>500000,"check","-") -> check | K6: 0 | L6: =+H6*(-1) -> 545250000 | P6: Vĩnh Phúc Nái | Q6: =IFERROR(SUMIFS('Heo thịt_Nhập dữ liệu hàng ngày'!$U:$U,'Heo thịt_Nhập dữ liệu hàng ngày'!$K:$K,">="&$P$4,'Heo thịt_Nhập dữ liệu hàng ngày'!$K:$K,"<="&'Theo dõi khách hàng heo thịt'!$Q$4,'Heo thịt_Nhập dữ liệu hàng ngày'!$L:$L,'Theo dõi khách hàng heo thịt'!P6,'Heo thịt_Nhập dữ liệu hàng ngày'!$M:$M,'Theo dõi khách hàng heo thịt'!$N$5),"-") -> 0 | R6: =IFERROR(SUMIFS('Heo thịt_Nhập dữ liệu hàng ngày'!$AB:$AB,'Heo thịt_Nhập dữ liệu hàng ngày'!$K:$K,">="&$P$4,'Heo thịt_Nhập dữ liệu hàng ngày'!$K:$K,"<="&'Theo dõi khách hàng heo thịt'!$Q$4,'Heo thịt_Nhập dữ liệu hàng ngày'!$L:$L,'Theo dõi khách hàng heo thịt'!P6,'Heo thịt_Nhập dữ liệu hàng ngày'!$M:$M,'Theo dõi khách hàng heo thịt'!$N$5),"-") -> 0 | S6: =IFERROR(SUMIFS('Heo thịt_Nhập dữ liệu hàng ngày'!$AC:$AC,'Heo thịt_Nhập dữ liệu hàng ngày'!$K:$K,">="&$P$4,'Heo thịt_Nhập dữ liệu hàng ngày'!$K:$K,"<="&'Theo dõi khách hàng heo thịt'!$Q$4,'Heo thịt_Nhập dữ liệu hàng ngày'!$L:$L,'Theo dõi khách hàng heo thịt'!P6,'Heo thịt_Nhập dữ liệu hàng ngày'!$M:$M,'Theo dõi khách hàng heo thịt'!$N$5),"-") -> 0 | T6: =IFERROR(SUMIFS('Heo thịt_Nhập dữ liệu hàng ngày'!$AD:$AD,'Heo thịt_Nhập dữ liệu hàng ngày'!$K:$K,">="&$P$4,'Heo thịt_Nhập dữ liệu hàng ngày'!$K:$K,"<="&'Theo dõi khách hàng heo thịt'!$Q$4,'Heo thịt_Nhập dữ liệu hàng ngày'!$L:$L,'Theo dõi khách hàng heo thịt'!P6,'Heo thịt_Nhập dữ liệu hàng ngày'!$M:$M,'Theo dõi khách hàng heo thịt'!$N$5),"-") -> 0 | U6: =IFERROR(+T6-S6,"-") -> 0
B7: 3 | C7: =IFERROR(Data!C6,"") -> 0 | D7: =SUMIFS('Heo thịt_Nhập dữ liệu hàng ngày'!$U:$U,'Heo thịt_Nhập dữ liệu hàng ngày'!$M:$M,'Theo dõi khách hàng heo thịt'!C7) -> 0 | E7: =SUMIFS('Heo thịt_Nhập dữ liệu hàng ngày'!$AB:$AB,'Heo thịt_Nhập dữ liệu hàng ngày'!$M:$M,'Theo dõi khách hàng heo thịt'!C7) -> 0 | F7: =SUMIFS('Heo thịt_Nhập dữ liệu hàng ngày'!$AC:$AC,'Heo thịt_Nhập dữ liệu hàng ngày'!$M:$M,'Theo dõi khách hàng heo thịt'!C7) -> 0 | G7: =SUMIFS('Heo thịt_Nhập dữ liệu hàng ngày'!$AD:$AD,'Heo thịt_Nhập dữ liệu hàng ngày'!$M:$M,'Theo dõi khách hàng heo thịt'!C7) -> 0 | H7: =+G7-F7 -> 0 | I7: =+ABS(H7) -> 0 | J7: =+IF(I7>500000,"check","-") -> - | K7: x | L7: =+H7*(-1) -> 0 | P7: Phú Xuyên | Q7: =IFERROR(SUMIFS('Heo thịt_Nhập dữ liệu hàng ngày'!$U:$U,'Heo thịt_Nhập dữ liệu hàng ngày'!$K:$K,">="&$P$4,'Heo thịt_Nhập dữ liệu hàng ngày'!$K:$K,"<="&'Theo dõi khách hàng heo thịt'!$Q$4,'Heo thịt_Nhập dữ liệu hàng ngày'!$L:$L,'Theo dõi khách hàng heo thịt'!P7,'Heo thịt_Nhập dữ liệu hàng ngày'!$M:$M,'Theo dõi khách hàng heo thịt'!$N$5),"-") -> 0 | R7: =IFERROR(SUMIFS('Heo thịt_Nhập dữ liệu hàng ngày'!$AB:$AB,'Heo thịt_Nhập dữ liệu hàng ngày'!$K:$K,">="&$P$4,'Heo thịt_Nhập dữ liệu hàng ngày'!$K:$K,"<="&'Theo dõi khách hàng heo thịt'!$Q$4,'Heo thịt_Nhập dữ liệu hàng ngày'!$L:$L,'Theo dõi khách hàng heo thịt'!P7,'Heo thịt_Nhập dữ liệu hàng ngày'!$M:$M,'Theo dõi khách hàng heo thịt'!$N$5),"-") -> 0 | S7: =IFERROR(SUMIFS('Heo thịt_Nhập dữ liệu hàng ngày'!$AC:$AC,'Heo thịt_Nhập dữ liệu hàng ngày'!$K:$K,">="&$P$4,'Heo thịt_Nhập dữ liệu hàng ngày'!$K:$K,"<="&'Theo dõi khách hàng heo thịt'!$Q$4,'Heo thịt_Nhập dữ liệu hàng ngày'!$L:$L,'Theo dõi khách hàng heo thịt'!P7,'Heo thịt_Nhập dữ liệu hàng ngày'!$M:$M,'Theo dõi khách hàng heo thịt'!$N$5),"-") -> 0 | T7: =IFERROR(SUMIFS('Heo thịt_Nhập dữ liệu hàng ngày'!$AD:$AD,'Heo thịt_Nhập dữ liệu hàng ngày'!$K:$K,">="&$P$4,'Heo thịt_Nhập dữ liệu hàng ngày'!$K:$K,"<="&'Theo dõi khách hàng heo thịt'!$Q$4,'Heo thịt_Nhập dữ liệu hàng ngày'!$L:$L,'Theo dõi khách hàng heo thịt'!P7,'Heo thịt_Nhập dữ liệu hàng ngày'!$M:$M,'Theo dõi khách hàng heo thịt'!$N$5),"-") -> 0 | U7: =IFERROR(+T7-S7,"-") -> 0
B8: 4 | C8: =IFERROR(Data!C7,"") -> nguyễn văn tân | D8: =SUMIFS('Heo thịt_Nhập dữ liệu hàng ngày'!$U:$U,'Heo thịt_Nhập dữ liệu hàng ngày'!$M:$M,'Theo dõi khách hàng heo thịt'!C8) -> 972000000 | E8: =SUMIFS('Heo thịt_Nhập dữ liệu hàng ngày'!$AB:$AB,'Heo thịt_Nhập dữ liệu hàng ngày'!$M:$M,'Theo dõi khách hàng heo thịt'!C8) -> 0 | F8: =SUMIFS('Heo thịt_Nhập dữ liệu hàng ngày'!$AC:$AC,'Heo thịt_Nhập dữ liệu hàng ngày'!$M:$M,'Theo dõi khách hàng heo thịt'!C8) -> 972000000 | G8: =SUMIFS('Heo thịt_Nhập dữ liệu hàng ngày'!$AD:$AD,'Heo thịt_Nhập dữ liệu hàng ngày'!$M:$M,'Theo dõi khách hàng heo thịt'!C8) -> 0 | H8: =+G8-F8 -> -972000000 | I8: =+ABS(H8) -> 972000000 | J8: =+IF(I8>500000,"check","-") -> check | K8: Thiếu 2/10 | L8: =+H8*(-1) -> 972000000 | P8: Bắc Giang Thịt | Q8: =IFERROR(SUMIFS('Heo thịt_Nhập dữ liệu hàng ngày'!$U:$U,'Heo thịt_Nhập dữ liệu hàng ngày'!$K:$K,">="&$P$4,'Heo thịt_Nhập dữ liệu hàng ngày'!$K:$K,"<="&'Theo dõi khách hàng heo thịt'!$Q$4,'Heo thịt_Nhập dữ liệu hàng ngày'!$L:$L,'Theo dõi khách hàng heo thịt'!P8,'Heo thịt_Nhập dữ liệu hàng ngày'!$M:$M,'Theo dõi khách hàng heo thịt'!$N$5),"-") -> 0 | R8: =IFERROR(SUMIFS('Heo thịt_Nhập dữ liệu hàng ngày'!$AB:$AB,'Heo thịt_Nhập dữ liệu hàng ngày'!$K:$K,">="&$P$4,'Heo thịt_Nhập dữ liệu hàng ngày'!$K:$K,"<="&'Theo dõi khách hàng heo thịt'!$Q$4,'Heo thịt_Nhập dữ liệu hàng ngày'!$L:$L,'Theo dõi khách hàng heo thịt'!P8,'Heo thịt_Nhập dữ liệu hàng ngày'!$M:$M,'Theo dõi khách hàng heo thịt'!$N$5),"-") -> 0 | S8: =IFERROR(SUMIFS('Heo thịt_Nhập dữ liệu hàng ngày'!$AC:$AC,'Heo thịt_Nhập dữ liệu hàng ngày'!$K:$K,">="&$P$4,'Heo thịt_Nhập dữ liệu hàng ngày'!$K:$K,"<="&'Theo dõi khách hàng heo thịt'!$Q$4,'Heo thịt_Nhập dữ liệu hàng ngày'!$L:$L,'Theo dõi khách hàng heo thịt'!P8,'Heo thịt_Nhập dữ liệu hàng ngày'!$M:$M,'Theo dõi khách hàng heo thịt'!$N$5),"-") -> 0 | T8: =IFERROR(SUMIFS('Heo thịt_Nhập dữ liệu hàng ngày'!$AD:$AD,'Heo thịt_Nhập dữ liệu hàng ngày'!$K:$K,">="&$P$4,'Heo thịt_Nhập dữ liệu hàng ngày'!$K:$K,"<="&'Theo dõi khách hàng heo thịt'!$Q$4,'Heo thịt_Nhập dữ liệu hàng ngày'!$L:$L,'Theo dõi khách hàng heo thịt'!P8,'Heo thịt_Nhập dữ liệu hàng ngày'!$M:$M,'Theo dõi khách hàng heo thịt'!$N$5),"-") -> 0 | U8: =IFERROR(+T8-S8,"-") -> 0
B9: 5 | C9: =IFERROR(Data!C8,"") -> 0 | D9: =SUMIFS('Heo thịt_Nhập dữ liệu hàng ngày'!$U:$U,'Heo thịt_Nhập dữ liệu hàng ngày'!$M:$M,'Theo dõi khách hàng heo thịt'!C9) -> 0 | E9: =SUMIFS('Heo thịt_Nhập dữ liệu hàng ngày'!$AB:$AB,'Heo thịt_Nhập dữ liệu hàng ngày'!$M:$M,'Theo dõi khách hàng heo thịt'!C9) -> 0 | F9: =SUMIFS('Heo thịt_Nhập dữ liệu hàng ngày'!$AC:$AC,'Heo thịt_Nhập dữ liệu hàng ngày'!$M:$M,'Theo dõi khách hàng heo thịt'!C9) -> 0 | G9: =SUMIFS('Heo thịt_Nhập dữ liệu hàng ngày'!$AD:$AD,'Heo thịt_Nhập dữ liệu hàng ngày'!$M:$M,'Theo dõi khách hàng heo thịt'!C9) -> 0 | H9: =+G9-F9 -> 0 | I9: =+ABS(H9) -> 0 | J9: =+IF(I9>500000,"check","-") -> - | K9: 1177293000 | L9: =+H9*(-1) -> 0 | P9: Bắc Giang Nái | Q9: =IFERROR(SUMIFS('Heo thịt_Nhập dữ liệu hàng ngày'!$U:$U,'Heo thịt_Nhập dữ liệu hàng ngày'!$K:$K,">="&$P$4,'Heo thịt_Nhập dữ liệu hàng ngày'!$K:$K,"<="&'Theo dõi khách hàng heo thịt'!$Q$4,'Heo thịt_Nhập dữ liệu hàng ngày'!$L:$L,'Theo dõi khách hàng heo thịt'!P9,'Heo thịt_Nhập dữ liệu hàng ngày'!$M:$M,'Theo dõi khách hàng heo thịt'!$N$5),"-") -> 0 | R9: =IFERROR(SUMIFS('Heo thịt_Nhập dữ liệu hàng ngày'!$AB:$AB,'Heo thịt_Nhập dữ liệu hàng ngày'!$K:$K,">="&$P$4,'Heo thịt_Nhập dữ liệu hàng ngày'!$K:$K,"<="&'Theo dõi khách hàng heo thịt'!$Q$4,'Heo thịt_Nhập dữ liệu hàng ngày'!$L:$L,'Theo dõi khách hàng heo thịt'!P9,'Heo thịt_Nhập dữ liệu hàng ngày'!$M:$M,'Theo dõi khách hàng heo thịt'!$N$5),"-") -> 0 | S9: =IFERROR(SUMIFS('Heo thịt_Nhập dữ liệu hàng ngày'!$AC:$AC,'Heo thịt_Nhập dữ liệu hàng ngày'!$K:$K,">="&$P$4,'Heo thịt_Nhập dữ liệu hàng ngày'!$K:$K,"<="&'Theo dõi khách hàng heo thịt'!$Q$4,'Heo thịt_Nhập dữ liệu hàng ngày'!$L:$L,'Theo dõi khách hàng heo thịt'!P9,'Heo thịt_Nhập dữ liệu hàng ngày'!$M:$M,'Theo dõi khách hàng heo thịt'!$N$5),"-") -> 0 | T9: =IFERROR(SUMIFS('Heo thịt_Nhập dữ liệu hàng ngày'!$AD:$AD,'Heo thịt_Nhập dữ liệu hàng ngày'!$K:$K,">="&$P$4,'Heo thịt_Nhập dữ liệu hàng ngày'!$K:$K,"<="&'Theo dõi khách hàng heo thịt'!$Q$4,'Heo thịt_Nhập dữ liệu hàng ngày'!$L:$L,'Theo dõi khách hàng heo thịt'!P9,'Heo thịt_Nhập dữ liệu hàng ngày'!$M:$M,'Theo dõi khách hàng heo thịt'!$N$5),"-") -> 0 | U9: =IFERROR(+T9-S9,"-") -> 0
B10: 6 | C10: =IFERROR(Data!C9,"") -> 0 | D10: =SUMIFS('Heo thịt_Nhập dữ liệu hàng ngày'!$U:$U,'Heo thịt_Nhập dữ liệu hàng ngày'!$M:$M,'Theo dõi khách hàng heo thịt'!C10) -> 0 | E10: =SUMIFS('Heo thịt_Nhập dữ liệu hàng ngày'!$AB:$AB,'Heo thịt_Nhập dữ liệu hàng ngày'!$M:$M,'Theo dõi khách hàng heo thịt'!C10) -> 0 | F10: =SUMIFS('Heo thịt_Nhập dữ liệu hàng ngày'!$AC:$AC,'Heo thịt_Nhập dữ liệu hàng ngày'!$M:$M,'Theo dõi khách hàng heo thịt'!C10) -> 0 | G10: =SUMIFS('Heo thịt_Nhập dữ liệu hàng ngày'!$AD:$AD,'Heo thịt_Nhập dữ liệu hàng ngày'!$M:$M,'Theo dõi khách hàng heo thịt'!C10) -> 0 | H10: =+G10-F10 -> 0 | I10: =+ABS(H10) -> 0 | J10: =+IF(I10>500000,"check","-") -> - | K10: 2253784759 | L10: =+H10*(-1) -> 0 | P10: Phú Thọ | Q10: =IFERROR(SUMIFS('Heo thịt_Nhập dữ liệu hàng ngày'!$U:$U,'Heo thịt_Nhập dữ liệu hàng ngày'!$K:$K,">="&$P$4,'Heo thịt_Nhập dữ liệu hàng ngày'!$K:$K,"<="&'Theo dõi khách hàng heo thịt'!$Q$4,'Heo thịt_Nhập dữ liệu hàng ngày'!$L:$L,'Theo dõi khách hàng heo thịt'!P10,'Heo thịt_Nhập dữ liệu hàng ngày'!$M:$M,'Theo dõi khách hàng heo thịt'!$N$5),"-") -> 0 | R10: =IFERROR(SUMIFS('Heo thịt_Nhập dữ liệu hàng ngày'!$AB:$AB,'Heo thịt_Nhập dữ liệu hàng ngày'!$K:$K,">="&$P$4,'Heo thịt_Nhập dữ liệu hàng ngày'!$K:$K,"<="&'Theo dõi khách hàng heo thịt'!$Q$4,'Heo thịt_Nhập dữ liệu hàng ngày'!$L:$L,'Theo dõi khách hàng heo thịt'!P10,'Heo thịt_Nhập dữ liệu hàng ngày'!$M:$M,'Theo dõi khách hàng heo thịt'!$N$5),"-") -> 0 | S10: =IFERROR(SUMIFS('Heo thịt_Nhập dữ liệu hàng ngày'!$AC:$AC,'Heo thịt_Nhập dữ liệu hàng ngày'!$K:$K,">="&$P$4,'Heo thịt_Nhập dữ liệu hàng ngày'!$K:$K,"<="&'Theo dõi khách hàng heo thịt'!$Q$4,'Heo thịt_Nhập dữ liệu hàng ngày'!$L:$L,'Theo dõi khách hàng heo thịt'!P10,'Heo thịt_Nhập dữ liệu hàng ngày'!$M:$M,'Theo dõi khách hàng heo thịt'!$N$5),"-") -> 0 | T10: =IFERROR(SUMIFS('Heo thịt_Nhập dữ liệu hàng ngày'!$AD:$AD,'Heo thịt_Nhập dữ liệu hàng ngày'!$K:$K,">="&$P$4,'Heo thịt_Nhập dữ liệu hàng ngày'!$K:$K,"<="&'Theo dõi khách hàng heo thịt'!$Q$4,'Heo thịt_Nhập dữ liệu hàng ngày'!$L:$L,'Theo dõi khách hàng heo thịt'!P10,'Heo thịt_Nhập dữ liệu hàng ngày'!$M:$M,'Theo dõi khách hàng heo thịt'!$N$5),"-") -> 0 | U10: =IFERROR(+T10-S10,"-") -> 0
B11: 7 | C11: =IFERROR(Data!C10,"") -> 0 | D11: =SUMIFS('Heo thịt_Nhập dữ liệu hàng ngày'!$U:$U,'Heo thịt_Nhập dữ liệu hàng ngày'!$M:$M,'Theo dõi khách hàng heo thịt'!C11) -> 0 | E11: =SUMIFS('Heo thịt_Nhập dữ liệu hàng ngày'!$AB:$AB,'Heo thịt_Nhập dữ liệu hàng ngày'!$M:$M,'Theo dõi khách hàng heo thịt'!C11) -> 0 | F11: =SUMIFS('Heo thịt_Nhập dữ liệu hàng ngày'!$AC:$AC,'Heo thịt_Nhập dữ liệu hàng ngày'!$M:$M,'Theo dõi khách hàng heo thịt'!C11) -> 0 | G11: =SUMIFS('Heo thịt_Nhập dữ liệu hàng ngày'!$AD:$AD,'Heo thịt_Nhập dữ liệu hàng ngày'!$M:$M,'Theo dõi khách hàng heo thịt'!C11) -> 0 | H11: =+G11-F11 -> 0 | I11: =+ABS(H11) -> 0 | J11: =+IF(I11>500000,"check","-") -> - | K11: Thiếu 18/9/2024 | L11: =+H11*(-1) -> 0 | P11: Phú Thọ 2 | Q11: =IFERROR(SUMIFS('Heo thịt_Nhập dữ liệu hàng ngày'!$U:$U,'Heo thịt_Nhập dữ liệu hàng ngày'!$K:$K,">="&$P$4,'Heo thịt_Nhập dữ liệu hàng ngày'!$K:$K,"<="&'Theo dõi khách hàng heo thịt'!$Q$4,'Heo thịt_Nhập dữ liệu hàng ngày'!$L:$L,'Theo dõi khách hàng heo thịt'!P11,'Heo thịt_Nhập dữ liệu hàng ngày'!$M:$M,'Theo dõi khách hàng heo thịt'!$N$5),"-") -> 0 | R11: =IFERROR(SUMIFS('Heo thịt_Nhập dữ liệu hàng ngày'!$AB:$AB,'Heo thịt_Nhập dữ liệu hàng ngày'!$K:$K,">="&$P$4,'Heo thịt_Nhập dữ liệu hàng ngày'!$K:$K,"<="&'Theo dõi khách hàng heo thịt'!$Q$4,'Heo thịt_Nhập dữ liệu hàng ngày'!$L:$L,'Theo dõi khách hàng heo thịt'!P11,'Heo thịt_Nhập dữ liệu hàng ngày'!$M:$M,'Theo dõi khách hàng heo thịt'!$N$5),"-") -> 0 | S11: =IFERROR(SUMIFS('Heo thịt_Nhập dữ liệu hàng ngày'!$AC:$AC,'Heo thịt_Nhập dữ liệu hàng ngày'!$K:$K,">="&$P$4,'Heo thịt_Nhập dữ liệu hàng ngày'!$K:$K,"<="&'Theo dõi khách hàng heo thịt'!$Q$4,'Heo thịt_Nhập dữ liệu hàng ngày'!$L:$L,'Theo dõi khách hàng heo thịt'!P11,'Heo thịt_Nhập dữ liệu hàng ngày'!$M:$M,'Theo dõi khách hàng heo thịt'!$N$5),"-") -> 0 | T11: =IFERROR(SUMIFS('Heo thịt_Nhập dữ liệu hàng ngày'!$AD:$AD,'Heo thịt_Nhập dữ liệu hàng ngày'!$K:$K,">="&$P$4,'Heo thịt_Nhập dữ liệu hàng ngày'!$K:$K,"<="&'Theo dõi khách hàng heo thịt'!$Q$4,'Heo thịt_Nhập dữ liệu hàng ngày'!$L:$L,'Theo dõi khách hàng heo thịt'!P11,'Heo thịt_Nhập dữ liệu hàng ngày'!$M:$M,'Theo dõi khách hàng heo thịt'!$N$5),"-") -> 0 | U11: =IFERROR(+T11-S11,"-") -> 0
B12: 8 | C12: =IFERROR(Data!C11,"") -> 0 | D12: =SUMIFS('Heo thịt_Nhập dữ liệu hàng ngày'!$U:$U,'Heo thịt_Nhập dữ liệu hàng ngày'!$M:$M,'Theo dõi khách hàng heo thịt'!C12) -> 0 | E12: =SUMIFS('Heo thịt_Nhập dữ liệu hàng ngày'!$AB:$AB,'Heo thịt_Nhập dữ liệu hàng ngày'!$M:$M,'Theo dõi khách hàng heo thịt'!C12) -> 0 | F12: =SUMIFS('Heo thịt_Nhập dữ liệu hàng ngày'!$AC:$AC,'Heo thịt_Nhập dữ liệu hàng ngày'!$M:$M,'Theo dõi khách hàng heo thịt'!C12) -> 0 | G12: =SUMIFS('Heo thịt_Nhập dữ liệu hàng ngày'!$AD:$AD,'Heo thịt_Nhập dữ liệu hàng ngày'!$M:$M,'Theo dõi khách hàng heo thịt'!C12) -> 0 | H12: =+G12-F12 -> 0 | I12: =+ABS(H12) -> 0 | J12: =+IF(I12>500000,"check","-") -> - | K12: 453612000 | L12: =+H12*(-1) -> 0 | P12: Yên Bái | Q12: =IFERROR(SUMIFS('Heo thịt_Nhập dữ liệu hàng ngày'!$U:$U,'Heo thịt_Nhập dữ liệu hàng ngày'!$K:$K,">="&$P$4,'Heo thịt_Nhập dữ liệu hàng ngày'!$K:$K,"<="&'Theo dõi khách hàng heo thịt'!$Q$4,'Heo thịt_Nhập dữ liệu hàng ngày'!$L:$L,'Theo dõi khách hàng heo thịt'!P12,'Heo thịt_Nhập dữ liệu hàng ngày'!$M:$M,'Theo dõi khách hàng heo thịt'!$N$5),"-") -> 0 | R12: =IFERROR(SUMIFS('Heo thịt_Nhập dữ liệu hàng ngày'!$AB:$AB,'Heo thịt_Nhập dữ liệu hàng ngày'!$K:$K,">="&$P$4,'Heo thịt_Nhập dữ liệu hàng ngày'!$K:$K,"<="&'Theo dõi khách hàng heo thịt'!$Q$4,'Heo thịt_Nhập dữ liệu hàng ngày'!$L:$L,'Theo dõi khách hàng heo thịt'!P12,'Heo thịt_Nhập dữ liệu hàng ngày'!$M:$M,'Theo dõi khách hàng heo thịt'!$N$5),"-") -> 0 | S12: =IFERROR(SUMIFS('Heo thịt_Nhập dữ liệu hàng ngày'!$AC:$AC,'Heo thịt_Nhập dữ liệu hàng ngày'!$K:$K,">="&$P$4,'Heo thịt_Nhập dữ liệu hàng ngày'!$K:$K,"<="&'Theo dõi khách hàng heo thịt'!$Q$4,'Heo thịt_Nhập dữ liệu hàng ngày'!$L:$L,'Theo dõi khách hàng heo thịt'!P12,'Heo thịt_Nhập dữ liệu hàng ngày'!$M:$M,'Theo dõi khách hàng heo thịt'!$N$5),"-") -> 0 | T12: =IFERROR(SUMIFS('Heo thịt_Nhập dữ liệu hàng ngày'!$AD:$AD,'Heo thịt_Nhập dữ liệu hàng ngày'!$K:$K,">="&$P$4,'Heo thịt_Nhập dữ liệu hàng ngày'!$K:$K,"<="&'Theo dõi khách hàng heo thịt'!$Q$4,'Heo thịt_Nhập dữ liệu hàng ngày'!$L:$L,'Theo dõi khách hàng heo thịt'!P12,'Heo thịt_Nhập dữ liệu hàng ngày'!$M:$M,'Theo dõi khách hàng heo thịt'!$N$5),"-") -> 0 | U12: =IFERROR(+T12-S12,"-") -> 0
B13: 9 | C13: =IFERROR(Data!C12,"") -> 0 | D13: =SUMIFS('Heo thịt_Nhập dữ liệu hàng ngày'!$U:$U,'Heo thịt_Nhập dữ liệu hàng ngày'!$M:$M,'Theo dõi khách hàng heo thịt'!C13) -> 0 | E13: =SUMIFS('Heo thịt_Nhập dữ liệu hàng ngày'!$AB:$AB,'Heo thịt_Nhập dữ liệu hàng ngày'!$M:$M,'Theo dõi khách hàng heo thịt'!C13) -> 0 | F13: =SUMIFS('Heo thịt_Nhập dữ liệu hàng ngày'!$AC:$AC,'Heo thịt_Nhập dữ liệu hàng ngày'!$M:$M,'Theo dõi khách hàng heo thịt'!C13) -> 0 | G13: =SUMIFS('Heo thịt_Nhập dữ liệu hàng ngày'!$AD:$AD,'Heo thịt_Nhập dữ liệu hàng ngày'!$M:$M,'Theo dõi khách hàng heo thịt'!C13) -> 0 | H13: =+G13-F13 -> 0 | I13: =+ABS(H13) -> 0 | J13: =+IF(I13>500000,"check","-") -> - | K13: x | L13: =+H13*(-1) -> 0 | P13: Lục Nam | Q13: =IFERROR(SUMIFS('Heo thịt_Nhập dữ liệu hàng ngày'!$U:$U,'Heo thịt_Nhập dữ liệu hàng ngày'!$K:$K,">="&$P$4,'Heo thịt_Nhập dữ liệu hàng ngày'!$K:$K,"<="&'Theo dõi khách hàng heo thịt'!$Q$4,'Heo thịt_Nhập dữ liệu hàng ngày'!$L:$L,'Theo dõi khách hàng heo thịt'!P13,'Heo thịt_Nhập dữ liệu hàng ngày'!$M:$M,'Theo dõi khách hàng heo thịt'!$N$5),"-") -> 0 | R13: =IFERROR(SUMIFS('Heo thịt_Nhập dữ liệu hàng ngày'!$AB:$AB,'Heo thịt_Nhập dữ liệu hàng ngày'!$K:$K,">="&$P$4,'Heo thịt_Nhập dữ liệu hàng ngày'!$K:$K,"<="&'Theo dõi khách hàng heo thịt'!$Q$4,'Heo thịt_Nhập dữ liệu hàng ngày'!$L:$L,'Theo dõi khách hàng heo thịt'!P13,'Heo thịt_Nhập dữ liệu hàng ngày'!$M:$M,'Theo dõi khách hàng heo thịt'!$N$5),"-") -> 0 | S13: =IFERROR(SUMIFS('Heo thịt_Nhập dữ liệu hàng ngày'!$AC:$AC,'Heo thịt_Nhập dữ liệu hàng ngày'!$K:$K,">="&$P$4,'Heo thịt_Nhập dữ liệu hàng ngày'!$K:$K,"<="&'Theo dõi khách hàng heo thịt'!$Q$4,'Heo thịt_Nhập dữ liệu hàng ngày'!$L:$L,'Theo dõi khách hàng heo thịt'!P13,'Heo thịt_Nhập dữ liệu hàng ngày'!$M:$M,'Theo dõi khách hàng heo thịt'!$N$5),"-") -> 0 | T13: =IFERROR(SUMIFS('Heo thịt_Nhập dữ liệu hàng ngày'!$AD:$AD,'Heo thịt_Nhập dữ liệu hàng ngày'!$K:$K,">="&$P$4,'Heo thịt_Nhập dữ liệu hàng ngày'!$K:$K,"<="&'Theo dõi khách hàng heo thịt'!$Q$4,'Heo thịt_Nhập dữ liệu hàng ngày'!$L:$L,'Theo dõi khách hàng heo thịt'!P13,'Heo thịt_Nhập dữ liệu hàng ngày'!$M:$M,'Theo dõi khách hàng heo thịt'!$N$5),"-") -> 0 | U13: =IFERROR(+T13-S13,"-") -> 0
B14: 10 | C14: =IFERROR(Data!C13,"") -> 0 | D14: =SUMIFS('Heo thịt_Nhập dữ liệu hàng ngày'!$U:$U,'Heo thịt_Nhập dữ liệu hàng ngày'!$M:$M,'Theo dõi khách hàng heo thịt'!C14) -> 0 | E14: =SUMIFS('Heo thịt_Nhập dữ liệu hàng ngày'!$AB:$AB,'Heo thịt_Nhập dữ liệu hàng ngày'!$M:$M,'Theo dõi khách hàng heo thịt'!C14) -> 0 | F14: =SUMIFS('Heo thịt_Nhập dữ liệu hàng ngày'!$AC:$AC,'Heo thịt_Nhập dữ liệu hàng ngày'!$M:$M,'Theo dõi khách hàng heo thịt'!C14) -> 0 | G14: =SUMIFS('Heo thịt_Nhập dữ liệu hàng ngày'!$AD:$AD,'Heo thịt_Nhập dữ liệu hàng ngày'!$M:$M,'Theo dõi khách hàng heo thịt'!C14) -> 0 | H14: =+G14-F14 -> 0 | I14: =+ABS(H14) -> 0 | J14: =+IF(I14>500000,"check","-") -> - | L14: =+H14*(-1) -> 0 | P14: Lục Ngạn | Q14: =IFERROR(SUMIFS('Heo thịt_Nhập dữ liệu hàng ngày'!$U:$U,'Heo thịt_Nhập dữ liệu hàng ngày'!$K:$K,">="&$P$4,'Heo thịt_Nhập dữ liệu hàng ngày'!$K:$K,"<="&'Theo dõi khách hàng heo thịt'!$Q$4,'Heo thịt_Nhập dữ liệu hàng ngày'!$L:$L,'Theo dõi khách hàng heo thịt'!P14,'Heo thịt_Nhập dữ liệu hàng ngày'!$M:$M,'Theo dõi khách hàng heo thịt'!$N$5),"-") -> 0 | R14: =IFERROR(SUMIFS('Heo thịt_Nhập dữ liệu hàng ngày'!$AB:$AB,'Heo thịt_Nhập dữ liệu hàng ngày'!$K:$K,">="&$P$4,'Heo thịt_Nhập dữ liệu hàng ngày'!$K:$K,"<="&'Theo dõi khách hàng heo thịt'!$Q$4,'Heo thịt_Nhập dữ liệu hàng ngày'!$L:$L,'Theo dõi khách hàng heo thịt'!P14,'Heo thịt_Nhập dữ liệu hàng ngày'!$M:$M,'Theo dõi khách hàng heo thịt'!$N$5),"-") -> 0 | S14: =IFERROR(SUMIFS('Heo thịt_Nhập dữ liệu hàng ngày'!$AC:$AC,'Heo thịt_Nhập dữ liệu hàng ngày'!$K:$K,">="&$P$4,'Heo thịt_Nhập dữ liệu hàng ngày'!$K:$K,"<="&'Theo dõi khách hàng heo thịt'!$Q$4,'Heo thịt_Nhập dữ liệu hàng ngày'!$L:$L,'Theo dõi khách hàng heo thịt'!P14,'Heo thịt_Nhập dữ liệu hàng ngày'!$M:$M,'Theo dõi khách hàng heo thịt'!$N$5),"-") -> 0 | T14: =IFERROR(SUMIFS('Heo thịt_Nhập dữ liệu hàng ngày'!$AD:$AD,'Heo thịt_Nhập dữ liệu hàng ngày'!$K:$K,">="&$P$4,'Heo thịt_Nhập dữ liệu hàng ngày'!$K:$K,"<="&'Theo dõi khách hàng heo thịt'!$Q$4,'Heo thịt_Nhập dữ liệu hàng ngày'!$L:$L,'Theo dõi khách hàng heo thịt'!P14,'Heo thịt_Nhập dữ liệu hàng ngày'!$M:$M,'Theo dõi khách hàng heo thịt'!$N$5),"-") -> 0 | U14: =IFERROR(+T14-S14,"-") -> 0
B15: 11 | C15: =IFERROR(Data!C14,"") -> 0 | D15: =SUMIFS('Heo thịt_Nhập dữ liệu hàng ngày'!$U:$U,'Heo thịt_Nhập dữ liệu hàng ngày'!$M:$M,'Theo dõi khách hàng heo thịt'!C15) -> 0 | E15: =SUMIFS('Heo thịt_Nhập dữ liệu hàng ngày'!$AB:$AB,'Heo thịt_Nhập dữ liệu hàng ngày'!$M:$M,'Theo dõi khách hàng heo thịt'!C15) -> 0 | F15: =SUMIFS('Heo thịt_Nhập dữ liệu hàng ngày'!$AC:$AC,'Heo thịt_Nhập dữ liệu hàng ngày'!$M:$M,'Theo dõi khách hàng heo thịt'!C15) -> 0 | G15: =SUMIFS('Heo thịt_Nhập dữ liệu hàng ngày'!$AD:$AD,'Heo thịt_Nhập dữ liệu hàng ngày'!$M:$M,'Theo dõi khách hàng heo thịt'!C15) -> 0 | H15: =+G15-F15 -> 0 | I15: =+ABS(H15) -> 0 | J15: =+IF(I15>500000,"check","-") -> - | L15: =+H15*(-1) -> 0 | P15: Tiger Thái Nguyên | Q15: =IFERROR(SUMIFS('Heo thịt_Nhập dữ liệu hàng ngày'!$U:$U,'Heo thịt_Nhập dữ liệu hàng ngày'!$K:$K,">="&$P$4,'Heo thịt_Nhập dữ liệu hàng ngày'!$K:$K,"<="&'Theo dõi khách hàng heo thịt'!$Q$4,'Heo thịt_Nhập dữ liệu hàng ngày'!$L:$L,'Theo dõi khách hàng heo thịt'!P15,'Heo thịt_Nhập dữ liệu hàng ngày'!$M:$M,'Theo dõi khách hàng heo thịt'!$N$5),"-") -> 0 | R15: =IFERROR(SUMIFS('Heo thịt_Nhập dữ liệu hàng ngày'!$AB:$AB,'Heo thịt_Nhập dữ liệu hàng ngày'!$K:$K,">="&$P$4,'Heo thịt_Nhập dữ liệu hàng ngày'!$K:$K,"<="&'Theo dõi khách hàng heo thịt'!$Q$4,'Heo thịt_Nhập dữ liệu hàng ngày'!$L:$L,'Theo dõi khách hàng heo thịt'!P15,'Heo thịt_Nhập dữ liệu hàng ngày'!$M:$M,'Theo dõi khách hàng heo thịt'!$N$5),"-") -> 0 | S15: =IFERROR(SUMIFS('Heo thịt_Nhập dữ liệu hàng ngày'!$AC:$AC,'Heo thịt_Nhập dữ liệu hàng ngày'!$K:$K,">="&$P$4,'Heo thịt_Nhập dữ liệu hàng ngày'!$K:$K,"<="&'Theo dõi khách hàng heo thịt'!$Q$4,'Heo thịt_Nhập dữ liệu hàng ngày'!$L:$L,'Theo dõi khách hàng heo thịt'!P15,'Heo thịt_Nhập dữ liệu hàng ngày'!$M:$M,'Theo dõi khách hàng heo thịt'!$N$5),"-") -> 0 | T15: =IFERROR(SUMIFS('Heo thịt_Nhập dữ liệu hàng ngày'!$AD:$AD,'Heo thịt_Nhập dữ liệu hàng ngày'!$K:$K,">="&$P$4,'Heo thịt_Nhập dữ liệu hàng ngày'!$K:$K,"<="&'Theo dõi khách hàng heo thịt'!$Q$4,'Heo thịt_Nhập dữ liệu hàng ngày'!$L:$L,'Theo dõi khách hàng heo thịt'!P15,'Heo thịt_Nhập dữ liệu hàng ngày'!$M:$M,'Theo dõi khách hàng heo thịt'!$N$5),"-") -> 0 | U15: =IFERROR(+T15-S15,"-") -> 0
B16: 12 | C16: =IFERROR(Data!C15,"") -> 0 | D16: =SUMIFS('Heo thịt_Nhập dữ liệu hàng ngày'!$U:$U,'Heo thịt_Nhập dữ liệu hàng ngày'!$M:$M,'Theo dõi khách hàng heo thịt'!C16) -> 0 | E16: =SUMIFS('Heo thịt_Nhập dữ liệu hàng ngày'!$AB:$AB,'Heo thịt_Nhập dữ liệu hàng ngày'!$M:$M,'Theo dõi khách hàng heo thịt'!C16) -> 0 | F16: =SUMIFS('Heo thịt_Nhập dữ liệu hàng ngày'!$AC:$AC,'Heo thịt_Nhập dữ liệu hàng ngày'!$M:$M,'Theo dõi khách hàng heo thịt'!C16) -> 0 | G16: =SUMIFS('Heo thịt_Nhập dữ liệu hàng ngày'!$AD:$AD,'Heo thịt_Nhập dữ liệu hàng ngày'!$M:$M,'Theo dõi khách hàng heo thịt'!C16) -> 0 | H16: =+G16-F16 -> 0 | I16: =+ABS(H16) -> 0 | J16: =+IF(I16>500000,"check","-") -> - | L16: =+H16*(-1) -> 0 | P16: Tiger Phú Thọ 3 (Thanh Sơn) | Q16: =IFERROR(SUMIFS('Heo thịt_Nhập dữ liệu hàng ngày'!$U:$U,'Heo thịt_Nhập dữ liệu hàng ngày'!$K:$K,">="&$P$4,'Heo thịt_Nhập dữ liệu hàng ngày'!$K:$K,"<="&'Theo dõi khách hàng heo thịt'!$Q$4,'Heo thịt_Nhập dữ liệu hàng ngày'!$L:$L,'Theo dõi khách hàng heo thịt'!P16,'Heo thịt_Nhập dữ liệu hàng ngày'!$M:$M,'Theo dõi khách hàng heo thịt'!$N$5),"-") -> 0 | R16: =IFERROR(SUMIFS('Heo thịt_Nhập dữ liệu hàng ngày'!$AB:$AB,'Heo thịt_Nhập dữ liệu hàng ngày'!$K:$K,">="&$P$4,'Heo thịt_Nhập dữ liệu hàng ngày'!$K:$K,"<="&'Theo dõi khách hàng heo thịt'!$Q$4,'Heo thịt_Nhập dữ liệu hàng ngày'!$L:$L,'Theo dõi khách hàng heo thịt'!P16,'Heo thịt_Nhập dữ liệu hàng ngày'!$M:$M,'Theo dõi khách hàng heo thịt'!$N$5),"-") -> 0 | S16: =IFERROR(SUMIFS('Heo thịt_Nhập dữ liệu hàng ngày'!$AC:$AC,'Heo thịt_Nhập dữ liệu hàng ngày'!$K:$K,">="&$P$4,'Heo thịt_Nhập dữ liệu hàng ngày'!$K:$K,"<="&'Theo dõi khách hàng heo thịt'!$Q$4,'Heo thịt_Nhập dữ liệu hàng ngày'!$L:$L,'Theo dõi khách hàng heo thịt'!P16,'Heo thịt_Nhập dữ liệu hàng ngày'!$M:$M,'Theo dõi khách hàng heo thịt'!$N$5),"-") -> 0 | T16: =IFERROR(SUMIFS('Heo thịt_Nhập dữ liệu hàng ngày'!$AD:$AD,'Heo thịt_Nhập dữ liệu hàng ngày'!$K:$K,">="&$P$4,'Heo thịt_Nhập dữ liệu hàng ngày'!$K:$K,"<="&'Theo dõi khách hàng heo thịt'!$Q$4,'Heo thịt_Nhập dữ liệu hàng ngày'!$L:$L,'Theo dõi khách hàng heo thịt'!P16,'Heo thịt_Nhập dữ liệu hàng ngày'!$M:$M,'Theo dõi khách hàng heo thịt'!$N$5),"-") -> 0 | U16: =IFERROR(+T16-S16,"-") -> 0
B17: 13 | C17: =IFERROR(Data!C16,"") -> 0 | D17: =SUMIFS('Heo thịt_Nhập dữ liệu hàng ngày'!$U:$U,'Heo thịt_Nhập dữ liệu hàng ngày'!$M:$M,'Theo dõi khách hàng heo thịt'!C17) -> 0 | E17: =SUMIFS('Heo thịt_Nhập dữ liệu hàng ngày'!$AB:$AB,'Heo thịt_Nhập dữ liệu hàng ngày'!$M:$M,'Theo dõi khách hàng heo thịt'!C17) -> 0 | F17: =SUMIFS('Heo thịt_Nhập dữ liệu hàng ngày'!$AC:$AC,'Heo thịt_Nhập dữ liệu hàng ngày'!$M:$M,'Theo dõi khách hàng heo thịt'!C17) -> 0 | G17: =SUMIFS('Heo thịt_Nhập dữ liệu hàng ngày'!$AD:$AD,'Heo thịt_Nhập dữ liệu hàng ngày'!$M:$M,'Theo dõi khách hàng heo thịt'!C17) -> 0 | H17: =+G17-F17 -> 0 | I17: =+ABS(H17) -> 0 | J17: =+IF(I17>500000,"check","-") -> - | L17: =+H17*(-1) -> 0 | P17: Tiger Thái Nguyên(Đồng Hỷ) | Q17: =IFERROR(SUMIFS('Heo thịt_Nhập dữ liệu hàng ngày'!$U:$U,'Heo thịt_Nhập dữ liệu hàng ngày'!$K:$K,">="&$P$4,'Heo thịt_Nhập dữ liệu hàng ngày'!$K:$K,"<="&'Theo dõi khách hàng heo thịt'!$Q$4,'Heo thịt_Nhập dữ liệu hàng ngày'!$L:$L,'Theo dõi khách hàng heo thịt'!P17,'Heo thịt_Nhập dữ liệu hàng ngày'!$M:$M,'Theo dõi khách hàng heo thịt'!$N$5),"-") -> 0 | R17: =IFERROR(SUMIFS('Heo thịt_Nhập dữ liệu hàng ngày'!$AB:$AB,'Heo thịt_Nhập dữ liệu hàng ngày'!$K:$K,">="&$P$4,'Heo thịt_Nhập dữ liệu hàng ngày'!$K:$K,"<="&'Theo dõi khách hàng heo thịt'!$Q$4,'Heo thịt_Nhập dữ liệu hàng ngày'!$L:$L,'Theo dõi khách hàng heo thịt'!P17,'Heo thịt_Nhập dữ liệu hàng ngày'!$M:$M,'Theo dõi khách hàng heo thịt'!$N$5),"-") -> 0 | S17: =IFERROR(SUMIFS('Heo thịt_Nhập dữ liệu hàng ngày'!$AC:$AC,'Heo thịt_Nhập dữ liệu hàng ngày'!$K:$K,">="&$P$4,'Heo thịt_Nhập dữ liệu hàng ngày'!$K:$K,"<="&'Theo dõi khách hàng heo thịt'!$Q$4,'Heo thịt_Nhập dữ liệu hàng ngày'!$L:$L,'Theo dõi khách hàng heo thịt'!P17,'Heo thịt_Nhập dữ liệu hàng ngày'!$M:$M,'Theo dõi khách hàng heo thịt'!$N$5),"-") -> 0 | T17: =IFERROR(SUMIFS('Heo thịt_Nhập dữ liệu hàng ngày'!$AD:$AD,'Heo thịt_Nhập dữ liệu hàng ngày'!$K:$K,">="&$P$4,'Heo thịt_Nhập dữ liệu hàng ngày'!$K:$K,"<="&'Theo dõi khách hàng heo thịt'!$Q$4,'Heo thịt_Nhập dữ liệu hàng ngày'!$L:$L,'Theo dõi khách hàng heo thịt'!P17,'Heo thịt_Nhập dữ liệu hàng ngày'!$M:$M,'Theo dõi khách hàng heo thịt'!$N$5),"-") -> 0 | U17: =IFERROR(+T17-S17,"-") -> 0
B18: 14 | C18: =IFERROR(Data!C17,"") -> 0 | D18: =SUMIFS('Heo thịt_Nhập dữ liệu hàng ngày'!$U:$U,'Heo thịt_Nhập dữ liệu hàng ngày'!$M:$M,'Theo dõi khách hàng heo thịt'!C18) -> 0 | E18: =SUMIFS('Heo thịt_Nhập dữ liệu hàng ngày'!$AB:$AB,'Heo thịt_Nhập dữ liệu hàng ngày'!$M:$M,'Theo dõi khách hàng heo thịt'!C18) -> 0 | F18: =SUMIFS('Heo thịt_Nhập dữ liệu hàng ngày'!$AC:$AC,'Heo thịt_Nhập dữ liệu hàng ngày'!$M:$M,'Theo dõi khách hàng heo thịt'!C18) -> 0 | G18: =SUMIFS('Heo thịt_Nhập dữ liệu hàng ngày'!$AD:$AD,'Heo thịt_Nhập dữ liệu hàng ngày'!$M:$M,'Theo dõi khách hàng heo thịt'!C18) -> 0 | H18: =+G18-F18 -> 0 | I18: =+ABS(H18) -> 0 | J18: =+IF(I18>500000,"check","-") -> - | L18: =+H18*(-1) -> 0 | P18: Tiger Thanh Hóa | Q18: =IFERROR(SUMIFS('Heo thịt_Nhập dữ liệu hàng ngày'!$U:$U,'Heo thịt_Nhập dữ liệu hàng ngày'!$K:$K,">="&$P$4,'Heo thịt_Nhập dữ liệu hàng ngày'!$K:$K,"<="&'Theo dõi khách hàng heo thịt'!$Q$4,'Heo thịt_Nhập dữ liệu hàng ngày'!$L:$L,'Theo dõi khách hàng heo thịt'!P18,'Heo thịt_Nhập dữ liệu hàng ngày'!$M:$M,'Theo dõi khách hàng heo thịt'!$N$5),"-") -> 0 | R18: =IFERROR(SUMIFS('Heo thịt_Nhập dữ liệu hàng ngày'!$AB:$AB,'Heo thịt_Nhập dữ liệu hàng ngày'!$K:$K,">="&$P$4,'Heo thịt_Nhập dữ liệu hàng ngày'!$K:$K,"<="&'Theo dõi khách hàng heo thịt'!$Q$4,'Heo thịt_Nhập dữ liệu hàng ngày'!$L:$L,'Theo dõi khách hàng heo thịt'!P18,'Heo thịt_Nhập dữ liệu hàng ngày'!$M:$M,'Theo dõi khách hàng heo thịt'!$N$5),"-") -> 0 | S18: =IFERROR(SUMIFS('Heo thịt_Nhập dữ liệu hàng ngày'!$AC:$AC,'Heo thịt_Nhập dữ liệu hàng ngày'!$K:$K,">="&$P$4,'Heo thịt_Nhập dữ liệu hàng ngày'!$K:$K,"<="&'Theo dõi khách hàng heo thịt'!$Q$4,'Heo thịt_Nhập dữ liệu hàng ngày'!$L:$L,'Theo dõi khách hàng heo thịt'!P18,'Heo thịt_Nhập dữ liệu hàng ngày'!$M:$M,'Theo dõi khách hàng heo thịt'!$N$5),"-") -> 0 | T18: =IFERROR(SUMIFS('Heo thịt_Nhập dữ liệu hàng ngày'!$AD:$AD,'Heo thịt_Nhập dữ liệu hàng ngày'!$K:$K,">="&$P$4,'Heo thịt_Nhập dữ liệu hàng ngày'!$K:$K,"<="&'Theo dõi khách hàng heo thịt'!$Q$4,'Heo thịt_Nhập dữ liệu hàng ngày'!$L:$L,'Theo dõi khách hàng heo thịt'!P18,'Heo thịt_Nhập dữ liệu hàng ngày'!$M:$M,'Theo dõi khách hàng heo thịt'!$N$5),"-") -> 0 | U18: =IFERROR(+T18-S18,"-") -> 0
B19: 15 | C19: =IFERROR(Data!C18,"") -> 0 | D19: =SUMIFS('Heo thịt_Nhập dữ liệu hàng ngày'!$U:$U,'Heo thịt_Nhập dữ liệu hàng ngày'!$M:$M,'Theo dõi khách hàng heo thịt'!C19) -> 0 | E19: =SUMIFS('Heo thịt_Nhập dữ liệu hàng ngày'!$AB:$AB,'Heo thịt_Nhập dữ liệu hàng ngày'!$M:$M,'Theo dõi khách hàng heo thịt'!C19) -> 0 | F19: =SUMIFS('Heo thịt_Nhập dữ liệu hàng ngày'!$AC:$AC,'Heo thịt_Nhập dữ liệu hàng ngày'!$M:$M,'Theo dõi khách hàng heo thịt'!C19) -> 0 | G19: =SUMIFS('Heo thịt_Nhập dữ liệu hàng ngày'!$AD:$AD,'Heo thịt_Nhập dữ liệu hàng ngày'!$M:$M,'Theo dõi khách hàng heo thịt'!C19) -> 0 | H19: =+G19-F19 -> 0 | I19: =+ABS(H19) -> 0 | J19: =+IF(I19>500000,"check","-") -> - | L19: =+H19*(-1) -> 0 | P19: Thanh Hóa Nái | Q19: =IFERROR(SUMIFS('Heo thịt_Nhập dữ liệu hàng ngày'!$U:$U,'Heo thịt_Nhập dữ liệu hàng ngày'!$K:$K,">="&$P$4,'Heo thịt_Nhập dữ liệu hàng ngày'!$K:$K,"<="&'Theo dõi khách hàng heo thịt'!$Q$4,'Heo thịt_Nhập dữ liệu hàng ngày'!$L:$L,'Theo dõi khách hàng heo thịt'!P19,'Heo thịt_Nhập dữ liệu hàng ngày'!$M:$M,'Theo dõi khách hàng heo thịt'!$N$5),"-") -> 0 | R19: =IFERROR(SUMIFS('Heo thịt_Nhập dữ liệu hàng ngày'!$AB:$AB,'Heo thịt_Nhập dữ liệu hàng ngày'!$K:$K,">="&$P$4,'Heo thịt_Nhập dữ liệu hàng ngày'!$K:$K,"<="&'Theo dõi khách hàng heo thịt'!$Q$4,'Heo thịt_Nhập dữ liệu hàng ngày'!$L:$L,'Theo dõi khách hàng heo thịt'!P19,'Heo thịt_Nhập dữ liệu hàng ngày'!$M:$M,'Theo dõi khách hàng heo thịt'!$N$5),"-") -> 0 | S19: =IFERROR(SUMIFS('Heo thịt_Nhập dữ liệu hàng ngày'!$AC:$AC,'Heo thịt_Nhập dữ liệu hàng ngày'!$K:$K,">="&$P$4,'Heo thịt_Nhập dữ liệu hàng ngày'!$K:$K,"<="&'Theo dõi khách hàng heo thịt'!$Q$4,'Heo thịt_Nhập dữ liệu hàng ngày'!$L:$L,'Theo dõi khách hàng heo thịt'!P19,'Heo thịt_Nhập dữ liệu hàng ngày'!$M:$M,'Theo dõi khách hàng heo thịt'!$N$5),"-") -> 0 | T19: =IFERROR(SUMIFS('Heo thịt_Nhập dữ liệu hàng ngày'!$AD:$AD,'Heo thịt_Nhập dữ liệu hàng ngày'!$K:$K,">="&$P$4,'Heo thịt_Nhập dữ liệu hàng ngày'!$K:$K,"<="&'Theo dõi khách hàng heo thịt'!$Q$4,'Heo thịt_Nhập dữ liệu hàng ngày'!$L:$L,'Theo dõi khách hàng heo thịt'!P19,'Heo thịt_Nhập dữ liệu hàng ngày'!$M:$M,'Theo dõi khách hàng heo thịt'!$N$5),"-") -> 0 | U19: =IFERROR(+T19-S19,"-") -> 0
